Workbook

Sheet БД
B1: Плоскостные спортивные сооружения | H1: Спортивные залы | N1: Плавательные бассейны
B2: (площадки и поля)
B3: 2010 | C3: 2015 | D3: 2020 | E3: 2021 | F3: 2022 | G3: 2023 | H3: 2010 | I3: 2015 | J3: 2020 | K3: 2021 | L3: 2022 | M3: 2023 | N3: 2010 | O3: 2015 | P3: 2020 | Q3: 2021 | R3: 2022 | S3: 2023
A4: Российская Федерация | B4: 129 637 | C4: 148 194 | D4: 154 000 | E4: 157206 | F4: 158944 | G4: 161662 | H4: 72 381 | I4: 72 016 | J4: 75 281 | K4: 76105 | L4: 76873 | M4: 77777 | N4: 4 237 | O4: 5 196 | P4: 6 229 | Q4: 6442 | R4: 6575 | S4: 6765 | T4: Российская Федерация
A5: Центральный | B5: 32 516 | C5: 40 280 | D5: 44 824 | E5: 46416 | F5: 47 322 | G5: 48554 | H5: 15 586 | I5: 16 859 | J5: 18 037 | K5: 18354 | L5: 18562 | M5: 18795 | N5: 1 216 | O5: 1 401 | P5: 1 741 | Q5: 1774 | R5: 1808 | S5: 1880 | T5: Центральный
A6: федеральный округ | T6: федеральный округ
A7: Белгородская область | B7: 3 088 | C7: 3 300 | D7: 3 283 | E7: 3321 | F7: 3 272 | G7: 3268 | H7: 800 | I7: 819 | J7: 875 | K7: 887 | L7: 899 | M7: 909 | N7: 129 | O7: 142 | P7: 159 | Q7: 154 | R7: 156 | S7: 149 | T7: Белгородская область
A8: Брянская область | B8: 1 571 | C8: 1 517 | D8: 1 426 | E8: 1394 | F8: 1 374 | G8: 1437 | H8: 682 | I8: 675 | J8: 646 | K8: 667 | L8: 686 | M8: 688 | N8: 38 | O8: 50 | P8: 49 | Q8: 53 | R8: 56 | S8: 57 | T8: Брянская область
A9: Владимирская область | B9: 1 381 | C9: 1 554 | D9: 1 716 | E9: 1778 | F9: 1 776 | G9: 1758 | H9: 673 | I9: 716 | J9: 811 | K9: 821 | L9: 847 | M9: 857 | N9: 43 | O9: 57 | P9: 68 | Q9: 69 | R9: 71 | S9: 71 | T9: Владимирская область
A10: Воронежская область | B10: 3 471 | C10: 4 171 | D10: 4 569 | E10: 4509 | F10: 4 296 | G10: 4331 | H10: 1 285 | I10: 1 428 | J10: 1 308 | K10: 1337 | L10: 1 338 | M10: 1350 | N10: 52 | O10: 83 | P10: 66 | Q10: 63 | R10: 72 | S10: 72 | T10: Воронежская область
A11: Ивановская область | B11: 667 | C11: 1 030 | D11: 1 064 | E11: 1066 | F11: 1 043 | G11: 1023 | H11: 407 | I11: 518 | J11: 529 | K11: 537 | L11: 542 | M11: 553 | N11: 24 | O11: 30 | P11: 35 | Q11: 37 | R11: 38 | S11: 38 | T11: Ивановская область
A12: Калужская область | B12: 1 032 | C12: 1 066 | D12: 918 | E12: 929 | F12: 930 | G12: 935 | H12: 530 | I12: 592 | J12: 618 | K12: 626 | L12: 625 | M12: 625 | N12: 28 | O12: 49 | P12: 71 | Q12: 74 | R12: 76 | S12: 79 | T12: Калужская область
A13: Костромская область | B13: 684 | C13: 653 | D13: 685 | E13: 708 | F13: 718 | G13: 720 | H13: 358 | I13: 380 | J13: 397 | K13: 408 | L13: 411 | M13: 413 | N13: 31 | O13: 32 | P13: 33 | Q13: 34 | R13: 33 | S13: 33 | T13: Костромская область
A14: Курская область | B14: 1 189 | C14: 1 159 | D14: 1 081 | E14: 1094 | F14: 1 095 | G14: 1099 | H14: 657 | I14: 659 | J14: 673 | K14: 680 | L14: 683 | M14: 679 | N14: 36 | O14: 35 | P14: 47 | Q14: 49 | R14: 49 | S14: 54 | T14: Курская область
A15: Липецкая область | B15: 1 734 | C15: 1 941 | D15: 2 074 | E15: 2112 | F15: 2 175 | G15: 2189 | H15: 569 | I15: 602 | J15: 626 | K15: 645 | L15: 654 | M15: 660 | N15: 33 | O15: 42 | P15: 52 | Q15: 57 | R15: 58 | S15: 59 | T15: Липецкая область
A16: Московская область | B16: 3 079 | C16: 4 901 | D16: 2 427 | E16: 2874 | F16: 3 001 | G16: 3381 | H16: 1 886 | I16: 2 207 | J16: 2 382 | K16: 2505 | L16: 2 528 | M16: 2594 | N16: 196 | O16: 271 | P16: 332 | Q16: 349 | R16: 348 | S16: 381 | T16: Московская область
A17: Орловская область | B17: 1 026 | C17: 1 071 | D17: 579 | E17: 576 | F17: 581 | G17: 585 | H17: 441 | I17: 586 | J17: 562 | K17: 571 | L17: 598 | M17: 518 | N17: 30 | O17: 32 | P17: 34 | Q17: 34 | R17: 34 | S17: 33 | T17: Орловская область
A18: Рязанская область | B18: 1 333 | C18: 1 359 | D18: 1 310 | E18: 1327 | F18: 1 329 | G18: 1334 | H18: 499 | I18: 516 | J18: 604 | K18: 617 | L18: 612 | M18: 621 | N18: 31 | O18: 41 | P18: 58 | Q18: 59 | R18: 59 | S18: 63 | T18: Рязанская область
A19: Смоленская область | B19: 1 173 | C19: 1 207 | D19: 1 303 | E19: 1315 | F19: 1 320 | G19: 1322 | H19: 934 | I19: 924 | J19: 913 | K19: 907 | L19: 925 | M19: 914 | N19: 33 | O19: 55 | P19: 63 | Q19: 66 | R19: 67 | S19: 66 | T19: Смоленская область
A20: Тамбовская область | B20: 2 223 | C20: 2 803 | D20: 2 874 | E20: 2876 | F20: 2 878 | G20: 2879 | H20: 533 | I20: 632 | J20: 653 | K20: 654 | L20: 656 | M20: 656 | N20: 25 | O20: 40 | P20: 41 | Q20: 41 | R20: 41 | S20: 42 | T20: Тамбовская область
A21: Тверская область | B21: 1 669 | C21: 1 947 | D21: 2 308 | E21: 2540 | F21: 2 578 | G21: 2672 | H21: 1 275 | I21: 819 | J21: 859 | K21: 873 | L21: 880 | M21: 889 | N21: 62 | O21: 57 | P21: 63 | Q21: 65 | R21: 68 | S21: 69 | T21: Тверская область
A22: Тульская область | B22: 1 064 | C22: 1 234 | D22: 1 313 | E22: 1331 | F22: 1 344 | G22: 1351 | H22: 557 | I22: 610 | J22: 623 | K22: 633 | L22: 638 | M22: 643 | N22: 30 | O22: 46 | P22: 50 | Q22: 49 | R22: 50 | S22: 49 | T22: Тульская область
A23: Ярославская область | B23: 1 048 | C23: 1 128 | D23: 1 263 | E23: 1270 | F23: 1 299 | G23: 1311 | H23: 577 | I23: 559 | J23: 566 | K23: 569 | L23: 569 | M23: 572 | N23: 30 | O23: 24 | P23: 29 | Q23: 30 | R23: 33 | S23: 33 | T23: Ярославская область
A24: г. Москва | B24: 5 084 | C24: 8 239 | D24: 14 631 | E24: 15396 | F24: 16 313 | G24: 16959 | H24: 2 923 | I24: 3 617 | J24: 4 392 | K24: 4417 | L24: 4 471 | M24: 4654 | N24: 365 | O24: 315 | P24: 491 | Q24: 491 | R24: 499 | S24: 532 | T24: г. Москва
A25: Северо-Западный | B25: 8 318 | C25: 9 622 | D25: 11 251 | E25: 11419 | F25: 11 470 | G25: 11688 | H25: 6 549 | I25: 6 258 | J25: 6 647 | K25: 6749 | L25: 6784 | M25: 6932 | N25: 409 | O25: 638 | P25: 789 | Q25: 826 | R25: 847 | S25: 868 | T25: Северо-Западный
A26: федеральный округ | T26: федеральный округ
A27: Республика Карелия | B27: 547 | C27: 624 | D27: 616 | E27: 623 | F27: 622 | G27: 612 | H27: 748 | I27: 384 | J27: 416 | K27: 421 | L27: 422 | M27: 416 | N27: 26 | O27: 30 | P27: 39 | Q27: 38 | R27: 38 | S27: 32 | T27: Республика Карелия
A28: Республика Коми | B28: 755 | C28: 800 | D28: 890 | E28: 933 | F28: 772 | G28: 781 | H28: 719 | I28: 585 | J28: 537 | K28: 537 | L28: 503 | M28: 501 | N28: 37 | O28: 41 | P28: 43 | Q28: 44 | R28: 43 | S28: 43 | T28: Республика Коми
A29: Архангельская область | B29: 696 | C29: 880 | D29: 1 106 | E29: 1128 | F29: 1 154 | G29: 1161 | H29: 657 | I29: 697 | J29: 791 | K29: 799 | L29: 805 | M29: 801 | N29: 35 | O29: 49 | P29: 57 | Q29: 57 | R29: 58 | S29: 58 | T29: Архангельская область
A30: в том числе: | T30: в том числе:
A31: Ненецкий автономный округ | B31: – | C31: 35 | D31: 35 | E31: 38 | F31: 39 | G31: 40 | H31: – | I31: 50 | J31: 87 | K31: 93 | L31: 96 | M31: 92 | N31: – | O31: 1 | P31: 2 | Q31: 2 | R31: 2 | S31: 2 | T31: Ненецкий автономный округ
A32: Архангельская область | B32: 696 | C32: 845 | D32: 1 071 | E32: 1090 | F32: 1 115 | G32: 1121 | H32: 657 | I32: 647 | J32: 704 | K32: 706 | L32: 709 | M32: 709 | N32: 35 | O32: 48 | P32: 55 | Q32: 55 | R32: 56 | S32: 56 | T32: Архангельская область
A33: без автономного округа | T33: без автономного округа
A34: Вологодская область | B34: 707 | C34: 806 | D34: 928 | E34: 908 | F34: 918 | G34: 924 | H34: 658 | I34: 648 | J34: 627 | K34: 632 | L34: 635 | M34: 717 | N34: 39 | O34: 48 | P34: 62 | Q34: 65 | R34: 59 | S34: 62 | T34: Вологодская область
A35: Калининградская область | B35: 1 015 | C35: 1 058 | D35: 1 113 | E35: 1125 | F35: 1 134 | G35: 1139 | H35: 399 | I35: 463 | J35: 463 | K35: 468 | L35: 470 | M35: 474 | N35: 23 | O35: 42 | P35: 46 | Q35: 51 | R35: 51 | S35: 51 | T35: Калининградская область
A36: Ленинградская область | B36: 827 | C36: 1 279 | D36: 1 828 | E36: 1882 | F36: 1 947 | G36: 2004 | H36: 638 | I36: 701 | J36: 815 | K36: 847 | L36: 864 | M36: 882 | N36: 33 | O36: 64 | P36: 92 | Q36: 93 | R36: 103 | S36: 102 | T36: Ленинградская область
A37: Мурманская область | B37: 212 | C37: 299 | D37: 351 | E37: 384 | F37: 395 | G37: 385 | H37: 537 | I37: 366 | J37: 388 | K37: 406 | L37: 404 | M37: 411 | N37: 36 | O37: 33 | P37: 42 | Q37: 45 | R37: 46 | S37: 45 | T37: Мурманская область
A38: Новгородская область | B38: 700 | C38: 786 | D38: 905 | E38: 923 | F38: 917 | G38: 920 | H38: 281 | I38: 300 | J38: 329 | K38: 331 | L38: 332 | M38: 337 | N38: 28 | O38: 33 | P38: 35 | Q38: 35 | R38: 35 | S38: 35 | T38: Новгородская область
A39: Псковская область | B39: 589 | C39: 551 | D39: 577 | E39: 627 | F39: 639 | G39: 657 | H39: 339 | I39: 341 | J39: 345 | K39: 337 | L39: 339 | M39: 348 | N39: 12 | O39: 14 | P39: 17 | Q39: 18 | R39: 19 | S39: 19 | T39: Псковская область
A40: г. Санкт-Петербург | B40: 2 270 | C40: 2 539 | D40: 2 937 | E40: 2886 | F40: 2 972 | G40: 3105 | H40: 1 573 | I40: 1 773 | J40: 1 936 | K40: 1971 | L40: 2 010 | M40: 2045 | N40: 140 | O40: 284 | P40: 356 | Q40: 380 | R40: 395 | S40: 421 | T40: г. Санкт-Петербург
...

Sheet БД2
A1: Регион | B1: Численность зрителей театров, на тыс чел | C1: Стадионы с трибунами на 1500 мест и более на 100 чел | D1: Численность пользователей библиотек на 1000 чел | E1: ВЫПУСК ГАЗЕТ на 1 000 человек населения | F1: Численность детей, отдохнувших в них за лето на 1000 человек | I1: Область | J1: Значение
A2: Белгородская область | B2: 152 | C2: =IFERROR(VLOOKUP($A2,'[1]спортивные сооружния'!A4:G112,7,FALSE)/'[1]Экономические факторы'!E2*100,0) -> 41.533951 | D2: =VLOOKUP($A2,[1]библиотеки!A4:N116,14,FALSE)/'[1]Экономические факторы'!G2*1000 -> 497.10135 | E2: =VLOOKUP($A2,[1]Газеты!$A$3:$G$111,7,FALSE) -> 852 | F2: ='[1]Культурные факторы'!F2/'[1]Экономические факторы'!G2*1000 -> 39.648164 | I2: Russia | J2: 10
A3: Брянская область | B3: 173 | C3: =IFERROR(VLOOKUP($A3,'[1]спортивные сооружния'!A5:G113,7,FALSE)/'[1]Экономические факторы'!E3*100,0) -> 54.989496 | D3: =VLOOKUP($A3,[1]библиотеки!A5:N117,14,FALSE)/'[1]Экономические факторы'!G3*1000 -> 426.29552 | E3: =VLOOKUP($A3,[1]Газеты!$A$3:$G$111,7,FALSE) -> 234 | F3: ='[1]Культурные факторы'!F3/'[1]Экономические факторы'!G3*1000 -> 28.97409 | I3: England | J3: 12
A4: Владимирская область | B4: 78 | C4: =IFERROR(VLOOKUP($A4,'[1]спортивные сооружния'!A6:G114,7,FALSE)/'[1]Экономические факторы'!E4*100,0) -> 62.203222 | D4: =VLOOKUP($A4,[1]библиотеки!A6:N118,14,FALSE)/'[1]Экономические факторы'!G4*1000 -> 383.99878 | E4: =VLOOKUP($A4,[1]Газеты!$A$3:$G$111,7,FALSE) -> 552 | F4: ='[1]Культурные факторы'!F4/'[1]Экономические факторы'!G4*1000 -> 35.34621 | I4: Germany | J4: 20
A5: Воронежская область | B5: 228 | C5: =IFERROR(VLOOKUP($A5,'[1]спортивные сооружния'!A7:G115,7,FALSE)/'[1]Экономические факторы'!E5*100,0) -> 22.961203 | D5: =VLOOKUP($A5,[1]библиотеки!A7:N119,14,FALSE)/'[1]Экономические факторы'!G5*1000 -> 342.2187 | E5: =VLOOKUP($A5,[1]Газеты!$A$3:$G$111,7,FALSE) -> 480 | F5: ='[1]Культурные факторы'!F5/'[1]Экономические факторы'!G5*1000 -> 30.526964
A6: Ивановская область | B6: 350 | C6: =IFERROR(VLOOKUP($A6,'[1]спортивные сооружния'!A8:G116,7,FALSE)/'[1]Экономические факторы'!E6*100,0) -> 33.072083 | D6: =VLOOKUP($A6,[1]библиотеки!A8:N120,14,FALSE)/'[1]Экономические факторы'!G6*1000 -> 428.30334 | E6: =VLOOKUP($A6,[1]Газеты!$A$3:$G$111,7,FALSE) -> 321 | F6: ='[1]Культурные факторы'!F6/'[1]Экономические факторы'!G6*1000 -> 28.038415
A7: Калужская область | B7: 205 | C7: =IFERROR(VLOOKUP($A7,'[1]спортивные сооружния'!A9:G117,7,FALSE)/'[1]Экономические факторы'!E7*100,0) -> 41.838263 | D7: =VLOOKUP($A7,[1]библиотеки!A9:N121,14,FALSE)/'[1]Экономические факторы'!G7*1000 -> 535.38001 | E7: =VLOOKUP($A7,[1]Газеты!$A$3:$G$111,7,FALSE) -> 622 | F7: ='[1]Культурные факторы'!F7/'[1]Экономические факторы'!G7*1000 -> 25.271434
A8: Костромская область | B8: 257 | C8: =IFERROR(VLOOKUP($A8,'[1]спортивные сооружния'!A10:G118,7,FALSE)/'[1]Экономические факторы'!E8*100,0) -> 63.782447 | D8: =VLOOKUP($A8,[1]библиотеки!A10:N122,14,FALSE)/'[1]Экономические факторы'!G8*1000 -> 762.84655 | E8: =VLOOKUP($A8,[1]Газеты!$A$3:$G$111,7,FALSE) -> 386 | F8: ='[1]Культурные факторы'!F8/'[1]Экономические факторы'!G8*1000 -> 44.322797
A9: Курская область | B9: 234 | C9: =IFERROR(VLOOKUP($A9,'[1]спортивные сооружния'!A11:G119,7,FALSE)/'[1]Экономические факторы'!E9*100,0) -> 25.45009 | D9: =VLOOKUP($A9,[1]библиотеки!A11:N123,14,FALSE)/'[1]Экономические факторы'!G9*1000 -> 503.34622 | E9: =VLOOKUP($A9,[1]Газеты!$A$3:$G$111,7,FALSE) -> 394 | F9: ='[1]Культурные факторы'!F9/'[1]Экономические факторы'!G9*1000 -> 27.335281
A10: Липецкая область | B10: 200 | C10: =IFERROR(VLOOKUP($A10,'[1]спортивные сооружния'!A12:G120,7,FALSE)/'[1]Экономические факторы'!E10*100,0) -> 47.299113 | D10: =VLOOKUP($A10,[1]библиотеки!A12:N124,14,FALSE)/'[1]Экономические факторы'!G10*1000 -> 443.42919 | E10: =VLOOKUP($A10,[1]Газеты!$A$3:$G$111,7,FALSE) -> 132 | F10: ='[1]Культурные факторы'!F10/'[1]Экономические факторы'!G10*1000 -> 39.236764
A11: Московская область | B11: 104 | C11: =IFERROR(VLOOKUP($A11,'[1]спортивные сооружния'!A13:G121,7,FALSE)/'[1]Экономические факторы'!E11*100,0) -> 60.423289 | D11: =VLOOKUP($A11,[1]библиотеки!A13:N125,14,FALSE)/'[1]Экономические факторы'!G11*1000 -> 171.6505 | E11: =VLOOKUP($A11,[1]Газеты!$A$3:$G$111,7,FALSE) -> 198 | F11: ='[1]Культурные факторы'!F11/'[1]Экономические факторы'!G11*1000 -> 12.113786
A12: Орловская область | B12: 327 | C12: =IFERROR(VLOOKUP($A12,'[1]спортивные сооружния'!A14:G122,7,FALSE)/'[1]Экономические факторы'!E12*100,0) -> 10.700361 | D12: =VLOOKUP($A12,[1]библиотеки!A14:N126,14,FALSE)/'[1]Экономические факторы'!G12*1000 -> 405.77617 | E12: =VLOOKUP($A12,[1]Газеты!$A$3:$G$111,7,FALSE) -> 188 | F12: ='[1]Культурные факторы'!F12/'[1]Экономические факторы'!G12*1000 -> 34.223827
A13: Рязанская область | B13: 264 | C13: =IFERROR(VLOOKUP($A13,'[1]спортивные сооружния'!A15:G123,7,FALSE)/'[1]Экономические факторы'!E13*100,0) -> 47.569765 | D13: =VLOOKUP($A13,[1]библиотеки!A15:N127,14,FALSE)/'[1]Экономические факторы'!G13*1000 -> 502.67973 | E13: =VLOOKUP($A13,[1]Газеты!$A$3:$G$111,7,FALSE) -> 408 | F13: ='[1]Культурные факторы'!F13/'[1]Экономические факторы'!G13*1000 -> 19.127703
A14: Смоленская область | B14: 169 | C14: =IFERROR(VLOOKUP($A14,'[1]спортивные сооружния'!A16:G124,7,FALSE)/'[1]Экономические факторы'!E14*100,0) -> 138.33333 | D14: =VLOOKUP($A14,[1]библиотеки!A16:N128,14,FALSE)/'[1]Экономические факторы'!G14*1000 -> 512.73148 | E14: =VLOOKUP($A14,[1]Газеты!$A$3:$G$111,7,FALSE) -> 2592 | F14: ='[1]Культурные факторы'!F14/'[1]Экономические факторы'!G14*1000 -> 16.203704
A15: Тамбовская область | B15: 255 | C15: =IFERROR(VLOOKUP($A15,'[1]спортивные сооружния'!A17:G125,7,FALSE)/'[1]Экономические факторы'!E15*100,0) -> 75.760745 | D15: =VLOOKUP($A15,[1]библиотеки!A17:N129,14,FALSE)/'[1]Экономические факторы'!G15*1000 -> 529.12266 | E15: =VLOOKUP($A15,[1]Газеты!$A$3:$G$111,7,FALSE) -> 154 | F15: ='[1]Культурные факторы'!F15/'[1]Экономические факторы'!G15*1000 -> 51.134581
A16: Тверская область | B16: 350 | C16: =IFERROR(VLOOKUP($A16,'[1]спортивные сооружния'!A18:G126,7,FALSE)/'[1]Экономические факторы'!E16*100,0) -> 119.31316 | D16: =VLOOKUP($A16,[1]библиотеки!A18:N130,14,FALSE)/'[1]Экономические факторы'!G16*1000 -> 465.94982 | E16: =VLOOKUP($A16,[1]Газеты!$A$3:$G$111,7,FALSE) -> 307 | F16: ='[1]Культурные факторы'!F16/'[1]Экономические факторы'!G16*1000 -> 46.261565
... A83: Чукотский автономный округ | B83: 0 | C83: =IFERROR(VLOOKUP($A83,'[1]спортивные сооружния'!A85:G193,7,FALSE)/'[1]Экономические факторы'!E83*100,0) -> 0 | D83: =VLOOKUP($A83,[1]библиотеки!A85:N197,14,FALSE)/'[1]Экономические факторы'!G83*1000 -> 541.66667 | E83: =VLOOKUP($A83,[1]Газеты!$A$3:$G$111,7,FALSE) -> 108 | F83: ='[1]Культурные факторы'!F83/'[1]Экономические факторы'!G83*1000 -> 87.5

Sheet Не выходит
A1: Библиотечный фонд на 1 000 человек населения на 2023г. (на конец года; экземпляров)
A2: Центральный ФО | B2: 7500
A3: Северо-Западный ФО | B3: 7555
A4: Южный ФО | B4: 4696
A5: Северо-Кавказский ФО | B5: 3578
A6: Приволжский ФО | B6: 6108
A7: Уральский ФО | B7: 4332
A8: Сибирский ФО | B8: 5433
A9: Дальневосточный ФО | B9: 6139

Sheet Столб с накоп
A1: ФО | B1: Плоскостные спортивные сооружения (площадки и поля)
A2: Центральный | B2: 48554
A3: Северо-Западный | B3: 11688
A4: Южный | B4: 18019
A5: Северо-Кавказский | B5: 9035
A6: Приволжский | B6: 33749
A7: Уральский | B7: 13060
A8: Сибирский | B8: 19146
A9: Дальневосточный | B9: 8411

Sheet Граф
B1: Численность зрителей театров, на тыс чел | C1: Стадионы с трибунами на 1500 мест и более | D1: Численность пользователей библиотек на 1000 чел | E1: ВЫПУСК ГАЗЕТ на 1 000 человек населения | F1: СРЕДНЕГОДОВАЯ ЧИСЛЕННОСТЬ ЗАНЯТЫХ на 100 чел | G1: Среднемесячная номинальная начисленная з/п работников организаций (рублей) | H1: ВРП на душу (руб.) | I1: Плотность населения чел/км2
A2: 2023 | B2: 284 | C2: 11.104968 | D2: 50831 | E2: 579 | F2: 72911.8 | G2: 74854 | H2: 958811.4 | I2: 8.57
A3: 2022 | B3: 245 | C3: 11.143933 | D3: 51691 | E3: 693 | F3: 71216.9 | G3: 65338 | H3: 830059.8 | I3: 8.56
A4: 2021 | B4: 173 | C4: 11.402904 | D4: 49672 | E4: 817 | F4: 70817.9 | G4: 57244 | H4: 639170 | I4: 8.53
A5: 2020 | B5: 109 | C5: 12.003605 | D5: 44028 | E5: 936 | F5: 69550.3 | G5: 51344 | H5: 647708.1 | I5: 8.54
A6: 2019 | B6: 280 | C6: 11.788837 | D6: 50404 | E6: 955 | F6: 71064.5 | G6: 47867 | H6: 614333.2 | I6: 8.57
A7: 2015 | B7: 261 | C7: 12.752892 | D7: 51992 | E7: 1382 | F7: 72424.9 | G7: 34030 | H7: 447395.3 | I7: 8.57
A8: 2010 | B8: 217 | C8: 13.320267 | D8: 55971 | E8: 1446 | F8: 71493.1 | G8: 20952 | H8: 263828.6 | I8: 8.36
A9: 2005 | B9: 195 | C9: 14.52847 | D9: 58088 | E9: 1234 | F9: - | G9: 8555 | H9: 125658.7 | I9: 8.38

Sheet Ящик с усом
A1: Регион | B1: Стадионы с трибунами на 1500 мест и более на 100 чел
A2: Белгородская область | B2: 41.533951
A3: Брянская область | B3: 54.989496
A4: Владимирская область | B4: 62.203222
A5: Воронежская область | B5: 22.961203
A6: Ивановская область | B6: 33.072083
A7: Калужская область | B7: 41.838263
A8: Костромская область | B8: 63.782447
A9: Курская область | B9: 25.45009
A10: Липецкая область | B10: 47.299113
A11: Московская область | B11: 60.423289
A12: Орловская область | B12: 10.700361
A13: Рязанская область | B13: 47.569765
... A83: Чукотский автономный округ | B83: 0

Sheet Столб
A1: Регион | B1: ВЫПУСК ГАЗЕТ на 1 000 человек населения
A2: Смоленская область | B2: 2592
A3: г. Москва | B3: 2383
A4: Республика Марий Эл | B4: 1618
A5: г. Санкт-Петербург | B5: 1313
A6: Архангельская область | B6: 1250
A7: Архангельская область без автономного округа | B7: 1250
A8: Нижегородская область | B8: 1201
A9: Ульяновская область | B9: 1143
A10: Вологодская область | B10: 1061
A11: Белгородская область | B11: 852

Sheet Круг
B1: 2010 | C1: 2023
A2: Центральный ФО | B2: 32 516 | C2: 48554
A3: Северо-Западный ФО | B3: 8 318 | C3: 11688
A4: Южный ФО | B4: 14 180 | C4: 18019
A5: Северо-Кавказский ФО | B5: 6 807 | C5: 9035
A6: Приволжский ФО | B6: 30 955 | C6: 33749
A7: Уральский ФО | B7: 10 717 | C7: 13060
A8: Сибирский ФО | B8: 17 663 | C8: 19146
A9: Дальневосточный ФО | B9: 8 481 | C9: 8411

Sheet Солн луч
A1: субъект РФ того же ФО | B1: АО в центре | C1: Плавательные бассейны, 2023
A2: Сибирский ФО | B2: Республика Алтай | C2: 2
A3: Сибирский ФО | B3: Республика Тыва | C3: 8
A4: Сибирский ФО | B4: Республика Хакасия | C4: 30
A5: Сибирский ФО | B5: Алтайский край | C5: 100
A6: Сибирский ФО | B6: Красноярский край | C6: 127
A7: Сибирский ФО | B7: Иркутская область | C7: 97
A8: Сибирский ФО | B8: Кемеровская область | C8: 132
A9: Сибирский ФО | B9: Новосибирская область | C9: 110
A10: Сибирский ФО | B10: Омская область | C10: 75
A11: Сибирский ФО | B11: Томская область | C11: 32
A12: Дальневосточный ФО | B12: Республика Бурятия | C12: 17
A13: Дальневосточный ФО | B13: Республика Саха (Якутия) | C13: 54
... A86: Центральный ФО | B86: г. Москва | C86: 532

Sheet Дерево
A1: субъект РФ того же ФО | B1: АО в центре | C1: Плавательные бассейны, 2023
A2: Сибирский ФО | B2: Республика Алтай | C2: 150
A3: Сибирский ФО | B3: Республика Тыва | C3: 259
A4: Сибирский ФО | B4: Республика Хакасия | C4: 282
A5: Сибирский ФО | B5: Алтайский край | C5: 1723
A6: Сибирский ФО | B6: Красноярский край | C6: 1581
A7: Сибирский ФО | B7: Иркутская область | C7: 1387
A8: Сибирский ФО | B8: Кемеровская область | C8: 1157
A9: Сибирский ФО | B9: Новосибирская область | C9: 1436
A10: Сибирский ФО | B10: Омская область | C10: 1186
A11: Сибирский ФО | B11: Томская область | C11: 598
A12: Дальневосточный ФО | B12: Республика Бурятия | C12: 576
A13: Дальневосточный ФО | B13: Республика Саха (Якутия) | C13: 874
... A86: Центральный ФО | B86: г. Москва | C86: 4654

Sheet Лист11
