Workbook
Name OLE_LINK1: Основные!$A$97
Name OLE_LINK2: Основные!$A$97

Sheet театры, музеи
A1: 7.1. ЧИСЛЕННОСТЬ ЗРИТЕЛЕЙ ТЕАТРОВ И ЧИСЛО ПОСЕЩЕНИЙ МУЗЕЕВ на 1 000 человек населения1);2)
B2: Численность зрителей театров, человек | I2: Число посещений музеев, человек
B3: 2010 | C3: 2015 | D3: 2020 | E3: 2021 | F3: 2022 | G3: 2023 | H3: Место, | I3: 2010 | J3: 2015 | K3: 2020 | L3: 2021 | M3: 2022 | N3: 2023 | O3: Место,
A4: Российская Федерация | B4: 217 | C4: 260 | D4: 109 | E4: 173 | F4: 245 | G4: 284 | I4: 567 | J4: 533 | K4: 400 | L4: 648 | M4: 827 | N4: 904
A5: Центральный | B5: 262 | C5: 315 | D5: 131 | E5: 169 | F5: 255 | G5: 303 | H5: 2 | I5: 647 | J5: 831 | K5: 505 | L5: 683 | M5: 932 | N5: 1023 | O5: 2
A6: федеральный округ
A7: Белгородская область | B7: 118 | C7: 134 | D7: 72 | E7: 111 | F7: 141 | G7: 152 | H7: 72 | I7: 436 | J7: 220 | K7: 361 | L7: 689 | M7: 782 | N7: 732 | O7: 29
A8: Брянская область | B8: 139 | C8: 182 | D8: 81 | E8: 94 | F8: 148 | G8: 173 | H8: 66 | I8: 786 | J8: 450 | K8: 437 | L8: 449 | M8: 845 | N8: 677 | O8: 33
A9: Владимирская область | B9: 115 | C9: 135 | D9: 63 | E9: 66 | F9: 66 | G9: 78 | H9: 82 | I9: 1 376 | J9: 1103 | K9: 585 | L9: 1133 | M9: 1 187 | N9: 1292 | O9: 12
A10: Воронежская область | B10: 159 | C10: 177 | D10: 65 | E10: 87 | F10: 158 | G10: 228 | H10: 49 | I10: 220 | J10: 133 | K10: 175 | L10: 320 | M10: 386 | N10: 401 | O10: 58
A11: Ивановская область | B11: 233 | C11: 248 | D11: 86 | E11: 187 | F11: 324 | G11: 350 | H11: 10 | I11: 409 | J11: 205 | K11: 186 | L11: 411 | M11: 514 | N11: 619 | O11: 34
A12: Калужская область | B12: 185 | C12: 203 | D12: 91 | E12: 173 | F12: 184 | G12: 205 | H12: 58 | I12: 464 | J12: 401 | K12: 391 | L12: 889 | M12: 1 080 | N12: 1108 | O12: 19
A13: Костромская область | B13: 245 | C13: 335 | D13: 147 | E13: 161 | F13: 264 | G13: 257 | H13: 37 | J13: 489 | K13: 598 | L13: 753 | M13: 1 125 | N13: 1124 | O13: 18
A14: Курская область | B14: 164 | C14: 187 | D14: 84 | E14: 75 | F14: 157 | G14: 234 | H14: 47 | I14: 309 | J14: 157 | K14: 243 | L14: 378 | M14: 496 | N14: 559 | O14: 39
A15: Липецкая область | B15: 138 | C15: 169 | D15: 60 | E15: 81 | F15: 160 | G15: 200 | H15: 61 | I15: 186 | J15: 174 | K15: 140 | L15: 156 | M15: 171 | N15: 198 | O15: 78
A16: Московская область | B16: 91 | C16: 140 | D16: 61 | E16: 81 | F16: 102 | G16: 104 | H16: 79 | I16: 378 | J16: 314 | K16: 368 | L16: 527 | M16: 646 | N16: 851 | O16: 23
A17: Орловская область | B17: 238 | C17: 212 | D17: 92 | E17: 125 | F17: 256 | G17: 327 | H17: 16 | I17: 314 | J17: 265 | K17: 194 | L17: 312 | M17: 366 | N17: 405 | O17: 57
A18: Рязанская область | B18: 198 | C18: 232 | D18: 120 | E18: 128 | F18: 197 | G18: 264 | H18: 33 | I18: 494 | J18: 496 | K18: 462 | L18: 783 | M18: 905 | N18: 1142 | O18: 17
A19: Смоленская область | B19: 113 | C19: 115 | D19: 56 | E19: 72 | F19: 125 | G19: 169 | H19: 69 | I19: 441 | J19: 376 | K19: 276 | L19: 598 | M19: 850 | N19: 813 | O19: 25
A20: Тамбовская область | B20: 138 | C20: 191 | D20: 94 | E20: 143 | F20: 209 | G20: 255 | H20: 39 | I20: 290 | J20: 162 | K20: 311 | L20: 430 | M20: 445 | N20: 619 | O20: 34
A21: Тверская область | B21: 181 | C21: 227 | D21: 95 | E21: 171 | F21: 281 | G21: 350 | H21: 10 | I21: 334 | J21: 236 | K21: 402 | L21: 601 | M21: 672 | N21: 746 | O21: 27
A22: Тульская область | B22: 209 | C22: 238 | D22: 82 | E22: 125 | F22: 187 | G22: 237 | H22: 45 | I22: 608 | J22: 613 | K22: 720 | L22: 1003 | M22: 1 269 | N22: 1506 | O22: 9
A23: Ярославская область | B23: 226 | C23: 269 | D23: 150 | E23: 202 | F23: 261 | G23: 287 | H23: 24 | I23: 1 402 | J23: 971 | K23: 1469 | L23: 2328 | M23: 2 863 | N23: 3070 | O23: 3
A24: г. Москва | B24: 527 | C24: 611 | D24: 240 | E24: 294 | F24: 452 | G24: 538 | H24: 3 | I24: 993 | J24: 1839 | K24: 697 | L24: 748 | M24: 1 208 | N24: 1256 | O24: 13
A25: Северо-Западный | B25: 279 | C25: 395 | D25: 179 | E25: 286 | F25: 390 | G25: 459 | H25: 1 | I25: 1 779 | J25: 1506 | K25: 1100 | L25: 1933 | M25: 2 502 | N25: 2822 | O25: 1
A26: федеральный округ
A27: Республика Карелия | B27: 166 | C27: 241 | D27: 142 | E27: 228 | F27: 269 | G27: 375 | H27: 8 | I27: 683 | J27: 278 | K27: 556 | L27: 899 | M27: 1 354 | N27: 1311 | O27: 11
A28: Республика Коми | B28: 163 | C28: 188 | D28: 101 | E28: 165 | F28: 232 | G28: 279 | H28: 26 | I28: 388 | J28: 204 | K28: 220 | L28: 330 | M28: 455 | N28: 446 | O28: 50
A29: Архангельская область | B29: 136 | C29: 190 | D29: 106 | E29: 176 | F29: 203 | G29: 256 | I29: 550 | J29: 546 | K29: 429 | L29: 941 | M29: 1 279 | N29: 1201
A30: в том числе:
A31: Ненецкий автономный округ | B31: – | C31: – | D31: – | E31: – | F31: – | G31: – | I31: 522 | J31: 439 | K31: 149 | L31: 378 | M31: 452 | N31: 438 | O31: 51
A32: Архангельская область без автономного округа | B32: 141 | C32: 198 | D32: 110 | E32: 184 | F32: 211 | G32: 267 | H32: 31 | I32: 551 | J32: 550 | K32: 440 | L32: 964 | M32: 1 314 | N32: 1234 | O32: 14
A33: Вологодская область | B33: 154 | C33: 164 | D33: 79 | E33: 148 | F33: 218 | G33: 264 | H33: 33 | I33: 895 | J33: 600 | K33: 595 | L33: 979 | M33: 1 095 | N33: 1196 | O33: 15
A34: Калинингpадская область | B34: 154 | C34: 209 | D34: 80 | E34: 111 | F34: 183 | G34: 211 | H34: 56 | I34: 981 | J34: 854 | K34: 965 | L34: 1957 | M34: 1 828 | N34: 2318 | O34: 4
A35: Ленинградская область | B35: 145 | C35: 119 | D35: 54 | E35: 95 | F35: 122 | G35: 126 | H35: 75 | I35: 731 | J35: 261 | K35: 448 | L35: 575 | M35: 696 | N35: 848 | O35: 24
A36: Мурманская область | B36: 139 | C36: 138 | D36: 65 | E36: 141 | F36: 205 | G36: 214 | H36: 54 | I36: 389 | J36: 359 | K36: 182 | L36: 356 | M36: 455 | N36: 540 | O36: 44
A37: Новгородская область | B37: 106 | C37: 130 | D37: 50 | E37: 60 | F37: 127 | G37: 115 | H37: 78 | I37: 1 095 | J37: 1129 | K37: 862 | L37: 1438 | M37: 1 910 | N37: 2200 | O37: 6
A38: Псковская область | B38: 151 | C38: 145 | D38: 61 | E38: 80 | F38: 172 | G38: 204 | H38: 59 | I38: 954 | J38: 1027 | K38: 1645 | L38: 2329 | M38: 2 581 | N38: 3211 | O38: 2
A39: г. Санкт-Петербург | B39: 517 | C39: 766 | D39: 444 | E39: 520 | F39: 695 | G39: 822 | H39: 1 | I39: 3 669 | J39: 3066 | K39: 1834 | L39: 3298 | M39: 4 450 | N39: 4987 | O39: 1
A40: Южный | B40: 124 | C40: 158 | D40: 67 | E40: 105 | F40: 153 | G40: 183 | H40: 7 | I40: 519 | J40: 388 | K40: 450 | L40: 672 | M40: 661 | N40: 671 | O40: 4
...

Sheet спортивные сооружния
A1: 7.2. ЧИСЛО СПОРТИВНЫХ СООРУЖЕНИЙ
B2: Стадионы с трибунами | H2: Плоскостные спортивные сооружения
B3: на 1500 мест и более | H3: (площадки и поля) | N3: Спортивные залы | T3: Плавательные бассейны
B4: 2010 | C4: 2015 | D4: 2020 | E4: 2021 | F4: 2022 | G4: 2023 | H4: 2010 | I4: 2015 | J4: 2020 | K4: 2021 | L4: 2022 | M4: 2023 | N4: 2010 | O4: 2015 | P4: 2020 | Q4: 2021 | R4: 2022 | S4: 2023 | T4: 2010 | U4: 2015 | V4: 2020 | W4: 2021 | X4: 2022 | Y4: 2023
A5: Российская Федерация | B5: 1 903 | C5: 1 877 | D5: 1 770 | E5: 1676 | F5: 1632 | G5: 1623 | H5: 129 637 | I5: 148 194 | J5: 154 000 | K5: 157206 | L5: 158944 | M5: 161662 | N5: 72 381 | O5: 72 016 | P5: 75 281 | Q5: 76105 | R5: 76873 | S5: 77777 | T5: 4 237 | U5: 5 196 | V5: 6 229 | W5: 6442 | X5: 6575 | Y5: 6765 | Z5: Российская Федерация
A6: Центральный | B6: 531 | C6: 465 | D6: 414 | E6: 410 | F6: 397 | G6: 395 | H6: 32 516 | I6: 40 280 | J6: 44 824 | K6: 46416 | L6: 47 322 | M6: 48554 | N6: 15 586 | O6: 16 859 | P6: 18 037 | Q6: 18354 | R6: 18562 | S6: 18795 | T6: 1 216 | U6: 1 401 | V6: 1 741 | W6: 1774 | X6: 1808 | Y6: 1880 | Z6: Центральный
A7: федеральный округ | Z7: федеральный округ
A8: Белгородская область | B8: 19 | C8: 25 | D8: 24 | E8: 24 | F8: 22 | G8: 23 | H8: 3 088 | I8: 3 300 | J8: 3 283 | K8: 3321 | L8: 3 272 | M8: 3268 | N8: 800 | O8: 819 | P8: 875 | Q8: 887 | R8: 899 | S8: 909 | T8: 129 | U8: 142 | V8: 159 | W8: 154 | X8: 156 | Y8: 149 | Z8: Белгородская область
A9: Брянская область | B9: 19 | C9: 30 | D9: 21 | E9: 17 | F9: 16 | G9: 18 | H9: 1 571 | I9: 1 517 | J9: 1 426 | K9: 1394 | L9: 1 374 | M9: 1437 | N9: 682 | O9: 675 | P9: 646 | Q9: 667 | R9: 686 | S9: 688 | T9: 38 | U9: 50 | V9: 49 | W9: 53 | X9: 56 | Y9: 57 | Z9: Брянская область
A10: Владимирская область | B10: 33 | C10: 33 | D10: 33 | E10: 33 | F10: 30 | G10: 28 | H10: 1 381 | I10: 1 554 | J10: 1 716 | K10: 1778 | L10: 1 776 | M10: 1758 | N10: 673 | O10: 716 | P10: 811 | Q10: 821 | R10: 847 | S10: 857 | T10: 43 | U10: 57 | V10: 68 | W10: 69 | X10: 71 | Y10: 71 | Z10: Владимирская область
A11: Воронежская область | B11: 29 | C11: 25 | D11: 10 | E11: 10 | F11: 10 | G11: 10 | H11: 3 471 | I11: 4 171 | J11: 4 569 | K11: 4509 | L11: 4 296 | M11: 4331 | N11: 1 285 | O11: 1 428 | P11: 1 308 | Q11: 1337 | R11: 1 338 | S11: 1350 | T11: 52 | U11: 83 | V11: 66 | W11: 63 | X11: 72 | Y11: 72 | Z11: Воронежская область
A12: Ивановская область | B12: 25 | C12: 21 | D12: 16 | E12: 16 | F12: 14 | G12: 14 | H12: 667 | I12: 1 030 | J12: 1 064 | K12: 1066 | L12: 1 043 | M12: 1023 | N12: 407 | O12: 518 | P12: 529 | Q12: 537 | R12: 542 | S12: 553 | T12: 24 | U12: 30 | V12: 35 | W12: 37 | X12: 38 | Y12: 38 | Z12: Ивановская область
A13: Калужская область | B13: 25 | C13: 18 | D13: 15 | E13: 15 | F13: 15 | G13: 15 | H13: 1 032 | I13: 1 066 | J13: 918 | K13: 929 | L13: 930 | M13: 935 | N13: 530 | O13: 592 | P13: 618 | Q13: 626 | R13: 625 | S13: 625 | T13: 28 | U13: 49 | V13: 71 | W13: 74 | X13: 76 | Y13: 79 | Z13: Калужская область
A14: Костромская область | B14: 17 | C14: 6 | D14: 6 | E14: 7 | F14: 6 | G14: 6 | H14: 684 | I14: 653 | J14: 685 | K14: 708 | L14: 718 | M14: 720 | N14: 358 | O14: 380 | P14: 397 | Q14: 408 | R14: 411 | S14: 413 | T14: 31 | U14: 32 | V14: 33 | W14: 34 | X14: 33 | Y14: 33 | Z14: Костромская область
A15: Курская область | B15: 15 | C15: 13 | D15: 11 | E15: 9 | F15: 9 | G15: 9 | H15: 1 189 | I15: 1 159 | J15: 1 081 | K15: 1094 | L15: 1 095 | M15: 1099 | N15: 657 | O15: 659 | P15: 673 | Q15: 680 | R15: 683 | S15: 679 | T15: 36 | U15: 35 | V15: 47 | W15: 49 | X15: 49 | Y15: 54 | Z15: Курская область
A16: Липецкая область | B16: 21 | C16: 21 | D16: 22 | E16: 22 | F16: 22 | G16: 22 | H16: 1 734 | I16: 1 941 | J16: 2 074 | K16: 2112 | L16: 2 175 | M16: 2189 | N16: 569 | O16: 602 | P16: 626 | Q16: 645 | R16: 654 | S16: 660 | T16: 33 | U16: 42 | V16: 52 | W16: 57 | X16: 58 | Y16: 59 | Z16: Липецкая область
A17: Московская область | B17: 129 | C17: 126 | D17: 123 | E17: 122 | F17: 119 | G17: 118 | H17: 3 079 | I17: 4 901 | J17: 2 427 | K17: 2874 | L17: 3 001 | M17: 3381 | N17: 1 886 | O17: 2 207 | P17: 2 382 | Q17: 2505 | R17: 2 528 | S17: 2594 | T17: 196 | U17: 271 | V17: 332 | W17: 349 | X17: 348 | Y17: 381 | Z17: Московская область
A18: Орловская область | B18: 14 | C18: 14 | D18: 3 | E18: 3 | F18: 3 | G18: 3 | H18: 1 026 | I18: 1 071 | J18: 579 | K18: 576 | L18: 581 | M18: 585 | N18: 441 | O18: 586 | P18: 562 | Q18: 571 | R18: 598 | S18: 518 | T18: 30 | U18: 32 | V18: 34 | W18: 34 | X18: 34 | Y18: 33 | Z18: Орловская область
A19: Рязанская область | B19: 13 | C19: 15 | D19: 13 | E19: 13 | F19: 13 | G19: 13 | H19: 1 333 | I19: 1 359 | J19: 1 310 | K19: 1327 | L19: 1 329 | M19: 1334 | N19: 499 | O19: 516 | P19: 604 | Q19: 617 | R19: 612 | S19: 621 | T19: 31 | U19: 41 | V19: 58 | W19: 59 | X19: 59 | Y19: 63 | Z19: Рязанская область
A20: Смоленская область | B20: 24 | C20: 24 | D20: 24 | E20: 24 | F20: 24 | G20: 24 | H20: 1 173 | I20: 1 207 | J20: 1 303 | K20: 1315 | L20: 1 320 | M20: 1322 | N20: 934 | O20: 924 | P20: 913 | Q20: 907 | R20: 925 | S20: 914 | T20: 33 | U20: 55 | V20: 63 | W20: 66 | X20: 67 | Y20: 66 | Z20: Смоленская область
A21: Тамбовская область | B21: 19 | C21: 21 | D21: 21 | E21: 21 | F21: 21 | G21: 21 | H21: 2 223 | I21: 2 803 | J21: 2 874 | K21: 2876 | L21: 2 878 | M21: 2879 | N21: 533 | O21: 632 | P21: 653 | Q21: 654 | R21: 656 | S21: 656 | T21: 25 | U21: 40 | V21: 41 | W21: 41 | X21: 41 | Y21: 42 | Z21: Тамбовская область
A22: Тверская область | B22: 19 | C22: 18 | D22: 17 | E22: 17 | F22: 17 | G22: 17 | H22: 1 669 | I22: 1 947 | J22: 2 308 | K22: 2540 | L22: 2 578 | M22: 2672 | N22: 1 275 | O22: 819 | P22: 859 | Q22: 873 | R22: 880 | S22: 889 | T22: 62 | U22: 57 | V22: 63 | W22: 65 | X22: 68 | Y22: 69 | Z22: Тверская область
A23: Тульская область | B23: 29 | C23: 20 | D23: 17 | E23: 17 | F23: 17 | G23: 17 | H23: 1 064 | I23: 1 234 | J23: 1 313 | K23: 1331 | L23: 1 344 | M23: 1351 | N23: 557 | O23: 610 | P23: 623 | Q23: 633 | R23: 638 | S23: 643 | T23: 30 | U23: 46 | V23: 50 | W23: 49 | X23: 50 | Y23: 49 | Z23: Тульская область
A24: Ярославская область | B24: 18 | C24: 13 | D24: 13 | E24: 13 | F24: 12 | G24: 8 | H24: 1 048 | I24: 1 128 | J24: 1 263 | K24: 1270 | L24: 1 299 | M24: 1311 | N24: 577 | O24: 559 | P24: 566 | Q24: 569 | R24: 569 | S24: 572 | T24: 30 | U24: 24 | V24: 29 | W24: 30 | X24: 33 | Y24: 33 | Z24: Ярославская область
A25: г. Москва | B25: 63 | C25: 22 | D25: 25 | E25: 27 | F25: 27 | G25: 29 | H25: 5 084 | I25: 8 239 | J25: 14 631 | K25: 15396 | L25: 16 313 | M25: 16959 | N25: 2 923 | O25: 3 617 | P25: 4 392 | Q25: 4417 | R25: 4 471 | S25: 4654 | T25: 365 | U25: 315 | V25: 491 | W25: 491 | X25: 499 | Y25: 532 | Z25: г. Москва
A26: Северо-Западный | B26: 104 | C26: 91 | D26: 83 | E26: 82 | F26: 80 | G26: 78 | H26: 8 318 | I26: 9 622 | J26: 11 251 | K26: 11419 | L26: 11 470 | M26: 11688 | N26: 6 549 | O26: 6 258 | P26: 6 647 | Q26: 6749 | R26: 6784 | S26: 6932 | T26: 409 | U26: 638 | V26: 789 | W26: 826 | X26: 847 | Y26: 868 | Z26: Северо-Западный
A27: федеральный округ | Z27: федеральный округ
A28: Республика Карелия | B28: 4 | C28: 4 | D28: 4 | E28: 4 | F28: 4 | G28: 3 | H28: 547 | I28: 624 | J28: 616 | K28: 623 | L28: 622 | M28: 612 | N28: 748 | O28: 384 | P28: 416 | Q28: 421 | R28: 422 | S28: 416 | T28: 26 | U28: 30 | V28: 39 | W28: 38 | X28: 38 | Y28: 32 | Z28: Республика Карелия
A29: Республика Коми | B29: 8 | C29: 7 | D29: 7 | E29: 7 | F29: 7 | G29: 7 | H29: 755 | I29: 800 | J29: 890 | K29: 933 | L29: 772 | M29: 781 | N29: 719 | O29: 585 | P29: 537 | Q29: 537 | R29: 503 | S29: 501 | T29: 37 | U29: 41 | V29: 43 | W29: 44 | X29: 43 | Y29: 43 | Z29: Республика Коми
A30: Архангельская область | B30: 13 | C30: 9 | D30: 8 | E30: 8 | F30: 8 | G30: 7 | H30: 696 | I30: 880 | J30: 1 106 | K30: 1128 | L30: 1 154 | M30: 1161 | N30: 657 | O30: 697 | P30: 791 | Q30: 799 | R30: 805 | S30: 801 | T30: 35 | U30: 49 | V30: 57 | W30: 57 | X30: 58 | Y30: 58 | Z30: Архангельская область
A31: в том числе: | Z31: в том числе:
A32: Ненецкий автономный округ | B32: – | C32: – | D32: – | E32: – | F32: – | G32: – | H32: – | I32: 35 | J32: 35 | K32: 38 | L32: 39 | M32: 40 | N32: – | O32: 50 | P32: 87 | Q32: 93 | R32: 96 | S32: 92 | T32: – | U32: 1 | V32: 2 | W32: 2 | X32: 2 | Y32: 2 | Z32: Ненецкий автономный округ
A33: Архангельская область без автономного округа | B33: 13 | C33: 9 | D33: 8 | E33: 8 | F33: 8 | G33: 7 | H33: 696 | I33: 845 | J33: 1 071 | K33: 1090 | L33: 1 115 | M33: 1121 | N33: 657 | O33: 647 | P33: 704 | Q33: 706 | R33: 709 | S33: 709 | T33: 35 | U33: 48 | V33: 55 | W33: 55 | X33: 56 | Y33: 56 | Z33: Архангельская область
A34: Вологодская область | B34: 15 | C34: 13 | D34: 10 | E34: 9 | F34: 9 | G34: 11 | H34: 707 | I34: 806 | J34: 928 | K34: 908 | L34: 918 | M34: 924 | N34: 658 | O34: 648 | P34: 627 | Q34: 632 | R34: 635 | S34: 717 | T34: 39 | U34: 48 | V34: 62 | W34: 65 | X34: 59 | Y34: 62 | Z34: Вологодская область
A35: Калинингpадская область | B35: 5 | C35: 6 | D35: 7 | E35: 7 | F35: 7 | G35: 6 | H35: 1 015 | I35: 1 058 | J35: 1 113 | K35: 1125 | L35: 1 134 | M35: 1139 | N35: 399 | O35: 463 | P35: 463 | Q35: 468 | R35: 470 | S35: 474 | T35: 23 | U35: 42 | V35: 46 | W35: 51 | X35: 51 | Y35: 51 | Z35: Калининградская область
A36: Ленинградская область | B36: 25 | C36: 26 | D36: 22 | E36: 23 | F36: 21 | G36: 20 | H36: 827 | I36: 1 279 | J36: 1 828 | K36: 1882 | L36: 1 947 | M36: 2004 | N36: 638 | O36: 701 | P36: 815 | Q36: 847 | R36: 864 | S36: 882 | T36: 33 | U36: 64 | V36: 92 | W36: 93 | X36: 103 | Y36: 102 | Z36: Ленинградская область
A37: Мурманская область | B37: 7 | C37: 7 | D37: 7 | E37: 7 | F37: 7 | G37: 6 | H37: 212 | I37: 299 | J37: 351 | K37: 384 | L37: 395 | M37: 385 | N37: 537 | O37: 366 | P37: 388 | Q37: 406 | R37: 404 | S37: 411 | T37: 36 | U37: 33 | V37: 42 | W37: 45 | X37: 46 | Y37: 45 | Z37: Мурманская область
A38: Новгородская область | B38: 4 | C38: 3 | D38: 2 | E38: 2 | F38: 2 | G38: 2 | H38: 700 | I38: 786 | J38: 905 | K38: 923 | L38: 917 | M38: 920 | N38: 281 | O38: 300 | P38: 329 | Q38: 331 | R38: 332 | S38: 337 | T38: 28 | U38: 33 | V38: 35 | W38: 35 | X38: 35 | Y38: 35 | Z38: Новгородская область
A39: Псковская область | B39: 10 | C39: 9 | D39: 8 | E39: 7 | F39: 7 | G39: 7 | H39: 589 | I39: 551 | J39: 577 | K39: 627 | L39: 639 | M39: 657 | N39: 339 | O39: 341 | P39: 345 | Q39: 337 | R39: 339 | S39: 348 | T39: 12 | U39: 14 | V39: 17 | W39: 18 | X39: 19 | Y39: 19 | Z39: Псковская область
A40: г. Санкт-Петербург | B40: 13 | C40: 7 | D40: 8 | E40: 8 | F40: 8 | G40: 9 | H40: 2 270 | I40: 2 539 | J40: 2 937 | K40: 2886 | L40: 2 972 | M40: 3105 | N40: 1 573 | O40: 1 773 | P40: 1 936 | Q40: 1971 | R40: 2 010 | S40: 2045 | T40: 140 | U40: 284 | V40: 356 | W40: 380 | X40: 395 | Y40: 421 | Z40: г. Санкт-Петербург
...

Sheet библиотеки
A1: 7.3. ОБЩЕДОСТУПНЫЕ БИБЛИОТЕКИ
B2: Библиотечный фонд на 1 000 человек населения1);2) | I2: Численность пользователей3),
B3: (на конец года; экземпляров) | I3: тыс. человек
B4: 2010 | C4: 2015 | D4: 2020 | E4: 2021 | F4: 2022 | G4: 2023 | H4: Место, | I4: 2010 | J4: 2015 | K4: 2020 | L4: 2021 | M4: 2022 | N4: 2023
H5: занимаемое
H6: в Российской
H7: Федерации
H8: 2023
A9: Российская Федерация | B9: 6 459 | C9: 5702 | D9: 5697 | E9: 5643 | F9: 5 591 | G9: 6066 | I9: 55 971 | J9: 51 992 | K9: 44 028 | L9: 49672 | M9: 51 691 | N9: 50831
A10: Центральный | B10: 6 934 | C10: 5941 | D10: 5819 | E10: 5762 | F10: 5 661 | G10: 7500 | H10: 2 | I10: 14 225 | J10: 12 448 | K10: 9 876 | L10: 11064 | M10: 11 025 | N10: 11088
A11: федеральный округ
A12: Белгородская область | B12: 6 973 | C12: 6597 | D12: 6047 | E12: 5994 | F12: 6 044 | G12: 6001 | H12: 47 | I12: 736 | J12: 750 | K12: 706 | L12: 789 | M12: 826 | N12: 746
A13: Брянская область | B13: 7 473 | C13: 7181 | D13: 7012 | E13: 7002 | F13: 6 870 | G13: 6792 | H13: 33 | I13: 617 | J13: 543 | K13: 464 | L13: 485 | M13: 484 | N13: 487
A14: Владимирская область | B14: 6 989 | C14: 6863 | D14: 6666 | E14: 6681 | F14: 6 621 | G14: 6592 | H14: 37 | I14: 580 | J14: 546 | K14: 439 | L14: 490 | M14: 495 | N14: 503
A15: Воронежская область | B15: 6 833 | C15: 4173 | D15: 6031 | E15: 6004 | F15: 5 967 | G15: 5899 | H15: 48 | I15: 884 | J15: 565 | K15: 694 | L15: 774 | M15: 865 | N15: 778
A16: Ивановская область | B16: 8 340 | C16: 6524 | D16: 8458 | E16: 8566 | F16: 8 560 | G16: 8511 | H16: 16 | I16: 475 | J16: 351 | K16: 289 | L16: 361 | M16: 383 | N16: 388
A17: Калужская область | B17: 7 775 | C17: 7027 | D17: 6808 | E17: 6702 | F17: 6 675 | G17: 6642 | H17: 34 | I17: 439 | J17: 418 | K17: 375 | L17: 400 | M17: 409 | N17: 572
A18: Костромская область | B18: 11 982 | C18: 10951 | D18: 10553 | E18: 10513 | F18: 10 356 | G18: 10260 | H18: 6 | I18: 286 | J18: 264 | K18: 252 | L18: 267 | M18: 284 | N18: 432
A19: Курская область | B19: 10 485 | C19: 8911 | D19: 8284 | E19: 8243 | F19: 8 195 | G19: 8072 | H19: 17 | I19: 593 | J19: 511 | K19: 443 | L19: 476 | M19: 492 | N19: 534
A20: Липецкая область | B20: 7 505 | C20: 6237 | D20: 6956 | E20: 6965 | F20: 6 908 | G20: 6891 | H20: 30 | I20: 562 | J20: 440 | K20: 414 | L20: 451 | M20: 456 | N20: 495
A21: Московская область | B21: 3 658 | C21: 2791 | D21: 2181 | E21: 2061 | F21: 1 928 | G21: 1831 | H21: 83 | I21: 1 791 | J21: 1 607 | K21: 1484 | L21: 1712 | M21: 1 756 | N21: 1485
A22: Орловская область | B22: 6 839 | C22: 6626 | D22: 6877 | E22: 6892 | F22: 6 841 | G22: 6796 | H22: 32 | I22: 328 | J22: 288 | K22: 244 | L22: 257 | M22: 259 | N22: 281
A23: Рязанская область | B23: 6 049 | C23: 5678 | D23: 5770 | E23: 5771 | F23: 5 806 | G23: 5850 | H23: 50 | I23: 507 | J23: 478 | K23: 434 | L23: 491 | M23: 492 | N23: 544
A24: Смоленская область | B24: 9 660 | C24: 9270 | D24: 9165 | E24: 9150 | F24: 9 132 | G24: 9143 | H24: 11 | I24: 595 | J24: 548 | K24: 431 | L24: 439 | M24: 442 | N24: 443
A25: Тамбовская область | B25: 9 119 | C25: 8838 | D25: 9180 | E25: 9284 | F25: 9 351 | G25: 9364 | H25: 8 | I25: 579 | J25: 506 | K25: 496 | L25: 515 | M25: 517 | N25: 506
A26: Тверская область | B26: 9 026 | C26: 7898 | D26: 7877 | E26: 7890 | F26: 7 894 | G26: 7809 | H26: 20 | I26: 595 | J26: 538 | K26: 432 | L26: 498 | M26: 511 | N26: 559
A27: Тульская область | B27: 6 143 | C27: 4556 | D27: 4601 | E27: 4492 | F27: 4 444 | G27: 4400 | H27: 70 | I27: 595 | J27: 534 | K27: 457 | L27: 521 | M27: 533 | N27: 452
A28: Ярославская область | B28: 7 502 | C28: 6732 | D28: 6786 | E28: 6735 | F28: 6 663 | G28: 6512 | H28: 39 | I28: 480 | J28: 555 | K28: 431 | L28: 519 | M28: 451 | N28: 451
A29: г. Москва | B29: 7 458 | C29: 6630 | D29: 6438 | E29: 6413 | F29: 6 266 | G29: 12054 | H29: 2 | I29: 3 583 | J29: 3 006 | K29: 1391 | L29: 1617 | M29: 1 371 | N29: 1431
A30: Северо-Западный | B30: 8 486 | C30: 7972 | D30: 7685 | E30: 7621 | F30: 7 435 | G30: 7555 | H30: 1 | I30: 5 029 | J30: 4 859 | K30: 4 180 | L30: 4619 | M30: 4 831 | N30: 4050
A31: федеральный округ
A32: Республика Карелия | B32: 8 320 | C32: 6749 | D32: 7510 | E32: 7550 | F32: 7 563 | G32: 7537 | H32: 22 | I32: 497 | J32: 218 | K32: 143 | L32: 147 | M32: 152 | N32: 167
A33: Республика Коми | B33: 8 141 | C33: 8219 | D33: 6411 | E33: 6405 | F33: 6 388 | G33: 6349 | H33: 41 | I33: 421 | J33: 391 | K33: 297 | L33: 334 | M33: 347 | N33: 346
A34: Архангельская область | B34: 7 527 | C34: 6876 | D34: 7577 | E34: 7609 | F34: 7 435 | G34: 7313 | I34: 446 | J34: 402 | K34: 356 | L34: 372 | M34: 392 | N34: 424
A35: в том числе:
A36: Ненецкий автономный округ | B36: 4 689 | C36: 7423 | D36: 9741 | E36: 9594 | F36: 9 421 | G36: 8902 | H36: 12 | I36: 14 | J36: 18 | K36: 23 | L36: 24 | M36: 24 | N36: 14
A37: Архангельская область без автономного округа | B37: 7 628 | C37: 6855 | D37: 7486 | E37: 7525 | F37: 7 349 | G37: 7243 | H37: 25 | I37: 432 | J37: 384 | K37: 332 | L37: 348 | M37: 368 | N37: 410
A38: Вологодская область | B38: 7 298 | C38: 6448 | D38: 6109 | E38: 6107 | F38: 6 115 | G38: 6058 | H38: 44 | I38: 543 | J38: 643 | K38: 639 | L38: 682 | M38: 738 | N38: 558
A39: Калинингpадская область | B39: 5 158 | C39: 4856 | D39: 4458 | E39: 4326 | F39: 4 284 | G39: 4206 | H39: 72 | I39: 371 | J39: 306 | K39: 257 | L39: 268 | M39: 283 | N39: 269
A40: Ленинградская область | B40: 3 212 | C40: 3944 | D40: 3412 | E40: 3329 | F40: 3 296 | G40: 3229 | H40: 78 | I40: 360 | J40: 454 | K40: 454 | L40: 538 | M40: 579 | N40: 413
...

Sheet Газеты
A1: 7.4. ВЫПУСК ГАЗЕТ на 1 000 человек населения1);2)
A2: (разовый тираж; экземпляров)
B3: 2010 | C3: 2015 | D3: 2020 | E3: 2021 | F3: 2022 | G3: 2023 | H3: Место, занимаемое
H4: в Российской
H5: Федерации
H6: 2023
A7: Российская Федерация | B7: 1 446 | C7: 1382 | D7: 936 | E7: 817 | F7: 693 | G7: 579
A8: Центральный | B8: 2 414 | C8: 2014 | D8: 1730 | E8: 1513 | F8: 1 328 | G8: 1053 | H8: 2
A9: федеральный округ
A10: Белгородская область | B10: 1 005 | C10: 4404 | D10: 1896 | E10: 2041 | F10: 2 163 | G10: 852 | H10: 47
A11: Брянская область | B11: 388 | C11: 550 | D11: 359 | E11: 296 | F11: 254 | G11: 234 | H11: 33
A12: Владимирская область | B12: 249 | C12: 795 | D12: 605 | E12: 817 | F12: 562 | G12: 552 | H12: 37
A13: Воронежская область | B13: 1 217 | C13: 1067 | D13: 460 | E13: 753 | F13: 470 | G13: 480 | H13: 48
A14: Ивановская область | B14: 420 | C14: 619 | D14: 549 | E14: 426 | F14: 376 | G14: 321 | H14: 16
A15: Калужская область | B15: 769 | C15: 1020 | D15: 820 | E15: 843 | F15: 676 | G15: 622 | H15: 34
A16: Костромская область | B16: 5 252 | C16: 748 | D16: 772 | E16: 361 | F16: 431 | G16: 386 | H16: 6
A17: Курская область | B17: 1 368 | C17: 1411 | D17: 1004 | E17: 1028 | F17: 1 061 | G17: 394 | H17: 17
A18: Липецкая область | B18: 508 | C18: 792 | D18: 240 | E18: 173 | F18: 140 | G18: 132 | H18: 30
A19: Московская область | B19: 745 | C19: 792 | D19: 287 | E19: 291 | F19: 244 | G19: 198 | H19: 83
A20: Орловская область | B20: 564 | C20: 708 | D20: 359 | E20: 423 | F20: 268 | G20: 188 | H20: 32
A21: Рязанская область | B21: 517 | C21: 551 | D21: 381 | E21: 373 | F21: 608 | G21: 408 | H21: 50
A22: Смоленская область | B22: 3 523 | C22: 5578 | D22: 3796 | E22: 3846 | F22: 3 369 | G22: 2592 | H22: 11
A23: Тамбовская область | B23: 362 | C23: 785 | D23: 179 | E23: 180 | F23: 171 | G23: 154 | H23: 8
A24: Тверская область | B24: 504 | C24: 602 | D24: 300 | E24: 305 | F24: 329 | G24: 307 | H24: 20
A25: Тульская область | B25: 597 | C25: 574 | D25: 333 | E25: 449 | F25: 263 | G25: 191 | H25: 70
A26: Ярославская область | B26: 617 | C26: 1048 | D26: 556 | E26: 961 | F26: 651 | G26: 509 | H26: 39
A27: г. Москва | B27: 5 929 | C27: 3860 | D27: 4095 | E27: 3297 | F27: 2 894 | G27: 2383 | H27: 2
A28: Северо-Западный | B28: 2 651 | C28: 2335 | D28: 1344 | E28: 1179 | F28: 913 | G28: 895 | H28: 1
A29: федеральный округ
A30: Республика Карелия | B30: 1 011 | C30: 2396 | D30: 1151 | E30: 1715 | F30: 1 301 | G30: 564 | H30: 22
A31: Республика Коми | B31: 827 | C31: 1322 | D31: 1018 | E31: 1022 | F31: 807 | G31: 770 | H31: 41
A32: Архангельская область | B32: 2 159 | C32: 2303 | D32: 1759 | E32: 1393 | F32: 1 130 | G32: 1250
A33: в том числе:
A34: Ненецкий автономный округ | B34: 349 | C34: 533 | D34: 1171 | E34: 795 | F34: 493 | G34: 866 | H34: 12
A35: Архангельская область без автономного округа | B35: 2 223 | C35: 2372 | D35: 1784 | E35: 1418 | F35: 1 158 | G35: 1250 | H35: 25
A36: Вологодская область | B36: 1 074 | C36: 1178 | D36: 833 | E36: 1130 | F36: 724 | G36: 1061 | H36: 44
A37: Калинингpадская область | B37: 987 | C37: 1741 | D37: 506 | E37: 469 | F37: 350 | G37: 319 | H37: 72
A38: Ленинградская область | B38: 351 | C38: 445 | D38: 207 | E38: 260 | F38: 153 | G38: 130 | H38: 78
A39: Мурманская область | B39: 819 | C39: 781 | D39: 397 | E39: 729 | F39: 210 | G39: 837 | H39: 24
A40: Новгородская область | B40: 1 485 | C40: 1889 | D40: 1495 | E40: 1288 | F40: 1 079 | G40: 717 | H40: 18
...

Sheet Лагеря
B1: ЧИСЛЕННОСТЬ ОТДОХНУВШИХ ДЕТЕЙ ЗА ЛЕТО В СУБЪЕКТЕ РОССИЙСКОЙ ФЕДЕРАЦИИ (тысяч человек)
B3: 2018 | C3: 20202) | D3: 2021 | E3: 2022 | F3: 2023
A4: Российская Федерация | B4: 4 274,4 | C4: 707.1 | D4: 3 597,5 | E4: 3 925,2 | F4: 4021.6
A5: Центральный | B5: 742 | C5: 168.2 | D5: 676.7 | E5: 720.6 | F5: 704.5
A6: федеральный округ
A7: Белгородская область | B7: 80.2 | C7: 16.2 | D7: 95.5 | E7: 89.6 | F7: 59.5
A8: Брянская область | B8: 36.4 | C8: 17.8 | D8: 32.8 | E8: 32.9 | F8: 33.1
A9: Владимирская область | B9: 46.7 | C9: – | D9: 40.7 | E9: 45.7 | F9: 46.3
A10: Воронежская область | B10: 61.2 | C10: 15.1 | D10: 47.8 | E10: 62.8 | F10: 69.4
A11: Ивановская область | B11: 21.2 | C11: 0.6 | D11: 23.2 | E11: 25.7 | F11: 25.4
A12: Калужская область | B12: 26 | C12: – | D12: 22.8 | E12: 25.8 | F12: 27
A13: Костромская область | B13: 21.6 | C13: 16.3 | D13: 20.9 | E13: 21.5 | F13: 25.1
A14: Курская область | B14: 34 | C14: 21.9 | D14: 38.2 | E14: 32.1 | F14: 29
A15: Липецкая область | B15: 46.3 | C15: 19.2 | D15: 38.1 | E15: 42.1 | F15: 43.8
A16: Московская область | B16: 103.9 | C16: 24 | D16: 86.5 | E16: 108 | F16: 104.8
A17: Орловская область | B17: 25.2 | C17: 0.3 | D17: 21.3 | E17: 22.1 | F17: 23.7
A18: Рязанская область | B18: 25.7 | C18: 8.5 | D18: 18.7 | E18: 21.5 | F18: 20.7
A19: Смоленская область | B19: 16.7 | C19: – | D19: 12.4 | E19: 13.9 | F19: 14
A20: Тамбовская область | B20: 56 | C20: 4.8 | D20: 48.4 | E20: 48.4 | F20: 48.9
A21: Тверская область | B21: 55.1 | C21: 7 | D21: 46.2 | E21: 50.7 | F21: 55.5
A22: Тульская область | B22: 42 | C22: – | D22: 36.1 | E22: 31.3 | F22: 31.3
A23: Ярославская область | B23: 40.3 | C23: 15.7 | D23: 39.5 | E23: 45.1 | F23: 46
A24: г. Москва | B24: 3.7 | C24: 0.9 | D24: 7.6 | E24: 1.3 | F24: 1.1
A25: Северо-Западный | B25: 278 | C25: 62.5 | D25: 234.6 | E25: 258.1 | F25: 275.7
A26: федеральный округ
A27: Республика Карелия | B27: 5.3 | C27: 1.2 | D27: 3.7 | E27: 4.5 | F27: 4.5
A28: Республика Коми | B28: 24.4 | C28: 10.1 | D28: 26.1 | E28: 27.1 | F28: 28.9
A29: Архангельская область | B29: 35.1 | C29: – | D29: 28.4 | E29: 29.9 | F29: 31.7
A30: в том числе:
A31: Ненецкий автономный округ | B31: 1.7 | C31: – | D31: 1.7 | E31: 1.8 | F31: 1.8
A32: Архангельская область без автономного округа | B32: 33.4 | C32: – | D32: 26.7 | E32: 28.1 | F32: 29.9
A33: Вологодская область | B33: 31 | C33: 6.2 | D33: 27.7 | E33: 31.7 | F33: 33.1
A34: Калинингpадская область | B34: 43.8 | C34: 30.5 | D34: 40.8 | E34: 44.3 | F34: 46.1
A35: Ленинградская область | B35: 69.9 | C35: 6.4 | D35: 48.4 | E35: 58.9 | F35: 60.5
A36: Мурманская область | B36: 7.4 | C36: 1.3 | D36: 6.8 | E36: 7.1 | F36: 7.3
A37: Новгородская область | B37: 19.3 | C37: 0.3 | D37: 15.7 | E37: 15.9 | F37: 16.4
A38: Псковская область | B38: 11.4 | C38: 4.2 | D38: 10.7 | E38: 11 | F38: 12
A39: г. Санкт-Петербург | B39: 30.5 | C39: 2.2 | D39: 26.3 | E39: 27.8 | F39: 35.2
A40: Южный | B40: 448.8 | C40: 101.8 | D40: 382 | E40: 392.7 | F40: 427.6
A41: федеральный округ
...

Sheet Культурные факторы (копия)
A1: Регион | B1: Численность зрителей театров, человек | C1: Стадионы с трибунами на 1500 мест и более | D1: Библиотечный фонд на 1 000 человек населения (на конец года; экземпляров) | E1: ВЫПУСК ГАЗЕТ на 1 000 человек населения | F1: Численность детей, отдохнувших в них за лето, тыс. человек | I1: Численность зрителей театров, человек | J1: Число посещений музеев, человек | K1: Стадионы с трибунами на 1500 мест и более | L1: Библиотечный фонд на 1 000 человек населения (на конец года; экземпляров) | M1: ВЫПУСК ГАЗЕТ на 1 000 человек населения | N1: Численность детей, отдохнувших в них за лето, тыс. человек
A2: Белгородская область | B2: =VLOOKUP($A2,'театры, музеи'!$A$2:$H$112,7,FALSE) -> 152 | C2: =VLOOKUP($A2,'спортивные сооружния'!A4:G112,7,FALSE) -> 23 | D2: =VLOOKUP($A2,библиотеки!A4:N116,11,FALSE) -> 706 | E2: =VLOOKUP($A2,Газеты!$A$3:$G$111,7,FALSE) -> 852 | F2: =VLOOKUP($A2,Лагеря!$A$3:$F$113,6,FALSE) -> 59.5
A3: Брянская область | B3: =VLOOKUP($A3,'театры, музеи'!$A$2:$H$112,7,FALSE) -> 173 | C3: =VLOOKUP($A3,'спортивные сооружния'!A5:G113,7,FALSE) -> 18 | D3: =VLOOKUP($A3,библиотеки!A5:H117,7,FALSE) -> 6792 | E3: =VLOOKUP($A3,Газеты!$A$3:$G$111,7,FALSE) -> 234 | F3: =VLOOKUP($A3,Лагеря!$A$3:$F$113,6,FALSE) -> 33.1
A4: Владимирская область | B4: =VLOOKUP($A4,'театры, музеи'!$A$2:$H$112,7,FALSE) -> 78 | C4: =VLOOKUP($A4,'спортивные сооружния'!A6:G114,7,FALSE) -> 28 | D4: =VLOOKUP($A4,библиотеки!A6:H118,7,FALSE) -> 6592 | E4: =VLOOKUP($A4,Газеты!$A$3:$G$111,7,FALSE) -> 552 | F4: =VLOOKUP($A4,Лагеря!$A$3:$F$113,6,FALSE) -> 46.3
A5: Воронежская область | B5: =VLOOKUP($A5,'театры, музеи'!$A$2:$H$112,7,FALSE) -> 228 | C5: =VLOOKUP($A5,'спортивные сооружния'!A7:G115,7,FALSE) -> 10 | D5: =VLOOKUP($A5,библиотеки!A7:H119,7,FALSE) -> 5899 | E5: =VLOOKUP($A5,Газеты!$A$3:$G$111,7,FALSE) -> 480 | F5: =VLOOKUP($A5,Лагеря!$A$3:$F$113,6,FALSE) -> 69.4
A6: Ивановская область | B6: =VLOOKUP($A6,'театры, музеи'!$A$2:$H$112,7,FALSE) -> 350 | C6: =VLOOKUP($A6,'спортивные сооружния'!A8:G116,7,FALSE) -> 14 | D6: =VLOOKUP($A6,библиотеки!A8:H120,7,FALSE) -> 8511 | E6: =VLOOKUP($A6,Газеты!$A$3:$G$111,7,FALSE) -> 321 | F6: =VLOOKUP($A6,Лагеря!$A$3:$F$113,6,FALSE) -> 25.4
A7: Калужская область | B7: =VLOOKUP($A7,'театры, музеи'!$A$2:$H$112,7,FALSE) -> 205 | C7: =VLOOKUP($A7,'спортивные сооружния'!A9:G117,7,FALSE) -> 15 | D7: =VLOOKUP($A7,библиотеки!A9:H121,7,FALSE) -> 6642 | E7: =VLOOKUP($A7,Газеты!$A$3:$G$111,7,FALSE) -> 622 | F7: =VLOOKUP($A7,Лагеря!$A$3:$F$113,6,FALSE) -> 27
A8: Костромская область | B8: =VLOOKUP($A8,'театры, музеи'!$A$2:$H$112,7,FALSE) -> 257 | C8: =VLOOKUP($A8,'спортивные сооружния'!A10:G118,7,FALSE) -> 6 | D8: =VLOOKUP($A8,библиотеки!A10:H122,7,FALSE) -> 10260 | E8: =VLOOKUP($A8,Газеты!$A$3:$G$111,7,FALSE) -> 386 | F8: =VLOOKUP($A8,Лагеря!$A$3:$F$113,6,FALSE) -> 25.1
A9: Курская область | B9: =VLOOKUP($A9,'театры, музеи'!$A$2:$H$112,7,FALSE) -> 234 | C9: =VLOOKUP($A9,'спортивные сооружния'!A11:G119,7,FALSE) -> 9 | D9: =VLOOKUP($A9,библиотеки!A11:H123,7,FALSE) -> 8072 | E9: =VLOOKUP($A9,Газеты!$A$3:$G$111,7,FALSE) -> 394 | F9: =VLOOKUP($A9,Лагеря!$A$3:$F$113,6,FALSE) -> 29
A10: Липецкая область | B10: =VLOOKUP($A10,'театры, музеи'!$A$2:$H$112,7,FALSE) -> 200 | C10: =VLOOKUP($A10,'спортивные сооружния'!A12:G120,7,FALSE) -> 22 | D10: =VLOOKUP($A10,библиотеки!A12:H124,7,FALSE) -> 6891 | E10: =VLOOKUP($A10,Газеты!$A$3:$G$111,7,FALSE) -> 132 | F10: =VLOOKUP($A10,Лагеря!$A$3:$F$113,6,FALSE) -> 43.8
A11: Московская область | B11: =VLOOKUP($A11,'театры, музеи'!$A$2:$H$112,7,FALSE) -> 104 | C11: =VLOOKUP($A11,'спортивные сооружния'!A13:G121,7,FALSE) -> 118 | D11: =VLOOKUP($A11,библиотеки!A13:H125,7,FALSE) -> 1831 | E11: =VLOOKUP($A11,Газеты!$A$3:$G$111,7,FALSE) -> 198 | F11: =VLOOKUP($A11,Лагеря!$A$3:$F$113,6,FALSE) -> 104.8
A12: Орловская область | B12: =VLOOKUP($A12,'театры, музеи'!$A$2:$H$112,7,FALSE) -> 327 | C12: =VLOOKUP($A12,'спортивные сооружния'!A14:G122,7,FALSE) -> 3 | D12: =VLOOKUP($A12,библиотеки!A14:H126,7,FALSE) -> 6796 | E12: =VLOOKUP($A12,Газеты!$A$3:$G$111,7,FALSE) -> 188 | F12: =VLOOKUP($A12,Лагеря!$A$3:$F$113,6,FALSE) -> 23.7
A13: Рязанская область | B13: =VLOOKUP($A13,'театры, музеи'!$A$2:$H$112,7,FALSE) -> 264 | C13: =VLOOKUP($A13,'спортивные сооружния'!A15:G123,7,FALSE) -> 13 | D13: =VLOOKUP($A13,библиотеки!A15:H127,7,FALSE) -> 5850 | E13: =VLOOKUP($A13,Газеты!$A$3:$G$111,7,FALSE) -> 408 | F13: =VLOOKUP($A13,Лагеря!$A$3:$F$113,6,FALSE) -> 20.7
A14: Смоленская область | B14: =VLOOKUP($A14,'театры, музеи'!$A$2:$H$112,7,FALSE) -> 169 | C14: =VLOOKUP($A14,'спортивные сооружния'!A16:G124,7,FALSE) -> 24 | D14: =VLOOKUP($A14,библиотеки!A16:H128,7,FALSE) -> 9143 | E14: =VLOOKUP($A14,Газеты!$A$3:$G$111,7,FALSE) -> 2592 | F14: =VLOOKUP($A14,Лагеря!$A$3:$F$113,6,FALSE) -> 14
... A32: Южный федеральный округ | B32: =VLOOKUP($A32,'театры, музеи'!$A$2:$H$112,7,FALSE) -> #N/A | C32: =VLOOKUP($A32,'спортивные сооружния'!A34:G142,7,FALSE) -> #N/A | D32: =VLOOKUP($A32,библиотеки!A34:H146,7,FALSE) -> #N/A | E32: =VLOOKUP($A32,Газеты!$A$3:$G$111,7,FALSE) -> 217 | F32: =VLOOKUP($A32,Лагеря!$A$3:$F$113,6,FALSE) -> #N/A
A33: Республика Адыгея | B33: =VLOOKUP($A33,'театры, музеи'!$A$2:$H$112,7,FALSE) -> 181 | C33: =VLOOKUP($A33,'спортивные сооружния'!A34:G143,7,FALSE) -> 3 | D33: =VLOOKUP($A33,библиотеки!A35:H147,7,FALSE) -> 4936 | E33: =VLOOKUP($A33,Газеты!$A$3:$G$111,7,FALSE) -> 186 | F33: =VLOOKUP($A33,Лагеря!$A$3:$F$113,6,FALSE) -> 4.9
A34: Республика Калмыкия | B34: =VLOOKUP($A34,'театры, музеи'!$A$2:$H$112,7,FALSE) -> 245 | C34: =VLOOKUP($A34,'спортивные сооружния'!A35:G144,7,FALSE) -> – | D34: =VLOOKUP($A34,библиотеки!A36:H148,7,FALSE) -> 9245 | E34: =VLOOKUP($A34,Газеты!$A$3:$G$111,7,FALSE) -> 142 | F34: =VLOOKUP($A34,Лагеря!$A$3:$F$113,6,FALSE) -> 7.2
A35: Республика Крым | B35: =VLOOKUP($A35,'театры, музеи'!$A$2:$H$112,7,FALSE) -> 228 | C35: =VLOOKUP($A35,'спортивные сооружния'!A36:G145,7,FALSE) -> 30 | D35: =VLOOKUP($A35,библиотеки!A37:H149,7,FALSE) -> 5223 | E35: =VLOOKUP($A35,Газеты!$A$3:$G$111,7,FALSE) -> 136 | F35: =VLOOKUP($A35,Лагеря!$A$3:$F$113,6,FALSE) -> 67.7
A36: Краснодарский край | B36: =VLOOKUP($A36,'театры, музеи'!$A$2:$H$112,7,FALSE) -> 103 | C36: =VLOOKUP($A36,'спортивные сооружния'!A37:G146,7,FALSE) -> 82 | D36: =VLOOKUP($A36,библиотеки!A38:H150,7,FALSE) -> 3875 | E36: =VLOOKUP($A36,Газеты!$A$3:$G$111,7,FALSE) -> 230 | F36: =VLOOKUP($A36,Лагеря!$A$3:$F$113,6,FALSE) -> 191.4
A37: Астраханская область | B37: =VLOOKUP($A37,'театры, музеи'!$A$2:$H$112,7,FALSE) -> 283 | C37: =VLOOKUP($A37,'спортивные сооружния'!A38:G147,7,FALSE) -> 8 | D37: =VLOOKUP($A37,библиотеки!A38:H151,7,FALSE) -> 6029 | E37: =VLOOKUP($A37,Газеты!$A$3:$G$111,7,FALSE) -> 104 | F37: =VLOOKUP($A37,Лагеря!$A$3:$F$113,6,FALSE) -> 14
A38: Волгоградская область | B38: =VLOOKUP($A38,'театры, музеи'!$A$2:$H$112,7,FALSE) -> 214 | C38: =VLOOKUP($A38,'спортивные сооружния'!A39:G148,7,FALSE) -> 35 | D38: =VLOOKUP($A38,библиотеки!A39:H152,7,FALSE) -> 5061 | E38: =VLOOKUP($A38,Газеты!$A$3:$G$111,7,FALSE) -> 156 | F38: =VLOOKUP($A38,Лагеря!$A$3:$F$113,6,FALSE) -> 78.3
A39: Ростовская область | B39: =VLOOKUP($A39,'театры, музеи'!$A$2:$H$112,7,FALSE) -> 204 | C39: =VLOOKUP($A39,'спортивные сооружния'!A40:G149,7,FALSE) -> 56 | D39: =VLOOKUP($A39,библиотеки!A40:H153,7,FALSE) -> 5036 | E39: =VLOOKUP($A39,Газеты!$A$3:$G$111,7,FALSE) -> 310 | F39: =VLOOKUP($A39,Лагеря!$A$3:$F$113,6,FALSE) -> 59.3
A40: г. Севастополь | B40: =VLOOKUP($A40,'театры, музеи'!$A$2:$H$112,7,FALSE) -> 358 | C40: =VLOOKUP($A40,'спортивные сооружния'!A41:G150,7,FALSE) -> 3 | D40: =VLOOKUP($A40,библиотеки!A41:H154,7,FALSE) -> 2693 | E40: =VLOOKUP($A40,Газеты!$A$3:$G$111,7,FALSE) -> 195 | F40: =VLOOKUP($A40,Лагеря!$A$3:$F$113,6,FALSE) -> 4.8
A41: Северо-Кавказский федеральный округ | B41: =VLOOKUP($A41,'театры, музеи'!$A$2:$H$112,7,FALSE) -> #N/A | C41: =VLOOKUP($A41,'спортивные сооружния'!A42:G151,7,FALSE) -> #N/A | D41: =VLOOKUP($A41,библиотеки!A42:H155,7,FALSE) -> #N/A | E41: =VLOOKUP($A41,Газеты!$A$3:$G$111,7,FALSE) -> #N/A | F41: =VLOOKUP($A41,Лагеря!$A$3:$F$113,6,FALSE) -> #N/A
A42: Республика Дагестан | B42: =VLOOKUP($A42,'театры, музеи'!$A$2:$H$112,7,FALSE) -> 122 | C42: =VLOOKUP($A42,'спортивные сооружния'!A43:G152,7,FALSE) -> 13 | D42: =VLOOKUP($A42,библиотеки!A43:H156,7,FALSE) -> 2339 | E42: =VLOOKUP($A42,Газеты!$A$3:$G$111,7,FALSE) -> 56 | F42: =VLOOKUP($A42,Лагеря!$A$3:$F$113,6,FALSE) -> 26.4
A43: Республика Ингушетия | B43: =VLOOKUP($A43,'театры, музеи'!$A$2:$H$112,7,FALSE) -> #N/A | C43: =VLOOKUP($A43,'спортивные сооружния'!A44:G153,7,FALSE) -> 4 | D43: =VLOOKUP($A43,библиотеки!A44:H157,7,FALSE) -> #N/A | E43: =VLOOKUP($A43,Газеты!$A$3:$G$111,7,FALSE) -> #N/A | F43: =VLOOKUP($A43,Лагеря!$A$3:$F$113,6,FALSE) -> 3.7
A44: Кабардино-Балкарская Республика | B44: =VLOOKUP($A44,'театры, музеи'!$A$2:$H$112,7,FALSE) -> 210 | C44: =VLOOKUP($A44,'спортивные сооружния'!A45:G154,7,FALSE) -> 11 | D44: =VLOOKUP($A44,библиотеки!A45:H158,7,FALSE) -> 5527 | E44: =VLOOKUP($A44,Газеты!$A$3:$G$111,7,FALSE) -> 49 | F44: =VLOOKUP($A44,Лагеря!$A$3:$F$113,6,FALSE) -> 2.6
A45: Карачаево-Черкесская Республика | B45: =VLOOKUP($A45,'театры, музеи'!$A$2:$H$112,7,FALSE) -> 99 | C45: =VLOOKUP($A45,'спортивные сооружния'!A46:G155,7,FALSE) -> 4 | D45: =VLOOKUP($A45,библиотеки!A46:H159,7,FALSE) -> 5343 | E45: =VLOOKUP($A45,Газеты!$A$3:$G$111,7,FALSE) -> 95 | F45: =VLOOKUP($A45,Лагеря!$A$3:$F$113,6,FALSE) -> 6.6
A46: Республика Северная Осетия | B46: =VLOOKUP($A46,'театры, музеи'!$A$2:$H$112,7,FALSE) -> 317 | C46: =VLOOKUP($A46,'спортивные сооружния'!A47:G156,7,FALSE) -> 12 | D46: =VLOOKUP($A46,библиотеки!A47:H160,7,FALSE) -> 4936 | E46: =VLOOKUP($A46,Газеты!$A$3:$G$111,7,FALSE) -> 85 | F46: =VLOOKUP($A46,Лагеря!$A$3:$F$113,6,FALSE) -> 16.5
A47: Чеченская Республика | B47: =VLOOKUP($A47,'театры, музеи'!$A$2:$H$112,7,FALSE) -> 154 | C47: =VLOOKUP($A47,'спортивные сооружния'!A48:G157,7,FALSE) -> 13 | D47: =VLOOKUP($A47,библиотеки!A48:H161,7,FALSE) -> 1483 | E47: =VLOOKUP($A47,Газеты!$A$3:$G$111,7,FALSE) -> 28 | F47: =VLOOKUP($A47,Лагеря!$A$3:$F$113,6,FALSE) -> 9
A48: Ставропольский край | B48: =VLOOKUP($A48,'театры, музеи'!$A$2:$H$112,7,FALSE) -> 117 | C48: =VLOOKUP($A48,'спортивные сооружния'!A49:G158,7,FALSE) -> 40 | D48: =VLOOKUP($A48,библиотеки!A49:H162,7,FALSE) -> 5289 | E48: =VLOOKUP($A48,Газеты!$A$3:$G$111,7,FALSE) -> 173 | F48: =VLOOKUP($A48,Лагеря!$A$3:$F$113,6,FALSE) -> 78.1
... A55: Чувашская Республика | B55: =VLOOKUP($A55,'театры, музеи'!$A$2:$H$112,7,FALSE) -> 388 | C55: =VLOOKUP($A55,'спортивные сооружния'!A56:G165,7,FALSE) -> 12 | D55: =VLOOKUP($A55,библиотеки!A56:H169,7,FALSE) -> 7548 | E55: =VLOOKUP($A55,Газеты!$A$3:$G$111,7,FALSE) -> 509 | F55: =VLOOKUP($A55,Лагеря!$A$3:$F$113,6,FALSE) -> 31.9
A56: Пермский край | B56: =VLOOKUP($A56,'театры, музеи'!$A$2:$H$112,7,FALSE) -> 349 | C56: =VLOOKUP($A56,'спортивные сооружния'!A56:G166,7,FALSE) -> 25 | D56: =VLOOKUP($A56,библиотеки!A57:H170,7,FALSE) -> 4738 | E56: =VLOOKUP($A56,Газеты!$A$3:$G$111,7,FALSE) -> 370 | F56: =VLOOKUP($A56,Лагеря!$A$3:$F$113,6,FALSE) -> 97.6
A57: Кировская область | B57: =VLOOKUP($A57,'театры, музеи'!$A$2:$H$112,7,FALSE) -> 236 | C57: =VLOOKUP($A57,'спортивные сооружния'!A57:G167,7,FALSE) -> 24 | D57: =VLOOKUP($A57,библиотеки!A58:H171,7,FALSE) -> 10482 | E57: =VLOOKUP($A57,Газеты!$A$3:$G$111,7,FALSE) -> 605 | F57: =VLOOKUP($A57,Лагеря!$A$3:$F$113,6,FALSE) -> 51.1
A58: Нижегородская область | B58: =VLOOKUP($A58,'театры, музеи'!$A$2:$H$112,7,FALSE) -> 317 | C58: =VLOOKUP($A58,'спортивные сооружния'!A57:G168,7,FALSE) -> 42 | D58: =VLOOKUP($A58,библиотеки!A59:H172,7,FALSE) -> 5806 | E58: =VLOOKUP($A58,Газеты!$A$3:$G$111,7,FALSE) -> 1201 | F58: =VLOOKUP($A58,Лагеря!$A$3:$F$113,6,FALSE) -> 97.5
A59: Оренбургская область | B59: =VLOOKUP($A59,'театры, музеи'!$A$2:$H$112,7,FALSE) -> 220 | C59: =VLOOKUP($A59,'спортивные сооружния'!A58:G169,7,FALSE) -> 35 | D59: =VLOOKUP($A59,библиотеки!A60:H173,7,FALSE) -> 6593 | E59: =VLOOKUP($A59,Газеты!$A$3:$G$111,7,FALSE) -> 291 | F59: =VLOOKUP($A59,Лагеря!$A$3:$F$113,6,FALSE) -> 61.5
A60: Пензенская область | B60: =VLOOKUP($A60,'театры, музеи'!$A$2:$H$112,7,FALSE) -> 175 | C60: =VLOOKUP($A60,'спортивные сооружния'!A58:G170,7,FALSE) -> 25 | D60: =VLOOKUP($A60,библиотеки!A61:H174,7,FALSE) -> 6641 | E60: =VLOOKUP($A60,Газеты!$A$3:$G$111,7,FALSE) -> 455 | F60: =VLOOKUP($A60,Лагеря!$A$3:$F$113,6,FALSE) -> 38.5
A61: Самарская область | B61: =VLOOKUP($A61,'театры, музеи'!$A$2:$H$112,7,FALSE) -> 277 | C61: =VLOOKUP($A61,'спортивные сооружния'!A59:G171,7,FALSE) -> 39 | D61: =VLOOKUP($A61,библиотеки!A62:H175,7,FALSE) -> 5198 | E61: =VLOOKUP($A61,Газеты!$A$3:$G$111,7,FALSE) -> 285 | F61: =VLOOKUP($A61,Лагеря!$A$3:$F$113,6,FALSE) -> 93.5
A62: Саратовская область | B62: =VLOOKUP($A62,'театры, музеи'!$A$2:$H$112,7,FALSE) -> 266 | C62: =VLOOKUP($A62,'спортивные сооружния'!A60:G172,7,FALSE) -> 24 | D62: =VLOOKUP($A62,библиотеки!A62:H176,7,FALSE) -> 5728 | E62: =VLOOKUP($A62,Газеты!$A$3:$G$111,7,FALSE) -> 405 | F62: =VLOOKUP($A62,Лагеря!$A$3:$F$113,6,FALSE) -> 50.8
A63: Ульяновская область | B63: =VLOOKUP($A63,'театры, музеи'!$A$2:$H$112,7,FALSE) -> 189 | C63: =VLOOKUP($A63,'спортивные сооружния'!A61:G173,7,FALSE) -> 17 | D63: =VLOOKUP($A63,библиотеки!A63:H177,7,FALSE) -> 6888 | E63: =VLOOKUP($A63,Газеты!$A$3:$G$111,7,FALSE) -> 1143 | F63: =VLOOKUP($A63,Лагеря!$A$3:$F$113,6,FALSE) -> 40.7
...

Sheet Лист2
J10: Стадионы с трибунами на 1500 мест и более | K10: Численность зрителей театров, человек | L10: Число посещений музеев, человек | M10: Библиотечный фонд на 1 000 человек населения (на конец года; экземпляров) | N10: Численность детей, отдохнувших в них за лето, тыс. человек
J11: 1903 | K11: 217 | L11: 567 | M11: 6459 | N11: 4893.9
B12: Стадионы с трибунами на 1500 мест и более | C12: Численность зрителей театров, человек | D12: Число посещений музеев, человек | E12: Библиотечный фонд на 1 000 человек населения (на конец года; экземпляров) | F12: Численность детей, отдохнувших в них за лето, тыс. человек | J12: 1877 | K12: 260 | L12: 533 | M12: 5702 | N12: 4661.2
A13: Стадионы с трибунами на 1500 мест и более | B13: 1 | J13: 1770 | K13: 109 | L13: 400 | M13: 5697 | N13: 707.1
A14: Численность зрителей театров, человек | B14: -0.13419137 | C14: 1 | J14: 1676 | K14: 173 | L14: 648 | M14: 5643 | N14: 3597.5
A15: Число посещений музеев, человек | B15: -0.73726512 | C15: 0.72302448 | D15: 1 | J15: 1632 | K15: 245 | L15: 827 | M15: 5591 | N15: 3925.2
A16: Библиотечный фонд на 1 000 человек населения (на конец года; экземпляров) | B16: 0.43303942 | C16: 0.24468532 | D16: 0.045815782 | E16: 1 | J16: 1623 | K16: 284 | L16: 904 | M16: 6066 | N16: 4021.6
A17: Численность детей, отдохнувших в них за лето, тыс. человек | B17: 0.1978466 | C17: 0.81379144 | D17: 0.45922712 | E17: 0.42158126 | F17: 1
K25: 0.99749431
K26: 0.99499491
K27: 0.97497453
K28: 19.427255
K29: 6
J32: MS | K32: df | L32: SS | M32: F
J33: 18757.354 | K33: 4 | L33: 75029.415 | M33: 49.699117
J34: 377.41825 | K34: 1 | L34: 377.41825
K35: 5 | L35: 75406.833
J37: t-статистика | K37: Коэффициенты | L37: Стандартная ошибка | M37: P-Значение | N37: Верхние 95% | O37: Нижние 95,0% | P37: Верхние 95,0%
J38: 6.6338723 | K38: 1304.2548 | L38: 196.60536 | M38: 0.095247914 | N38: 3802.3628 | O38: -1193.8531 | P38: 3802.3628
J39: 0.4051535 | K39: 0.14607247 | L39: 0.36053612 | M39: 0.75493886 | N39: 4.7271183 | O39: -4.4349733 | P39: 4.7271183
J40: 0.55415539 | K40: 0.15855364 | L40: 0.28611766 | M40: 0.67785261 | N40: 3.7940231 | O40: -3.4769159 | P40: 3.7940231
J41: 3.4323529 | K41: 0.43672626 | L41: 0.12723816 | M41: 0.18048039 | N41: 2.0534403 | O41: -1.1799878 | P41: 2.0534403
J42: -1.4392028 | K42: -0.032277477 | L42: 0.02242733 | M42: 0.38658553 | N42: 0.25268877 | O42: -0.31724373 | P42: 0.25268877
K49: Предсказанное Стадионы с трибунами на 1500 мест и более | L49: Остатки
K50: 1903 | L50: -2.2737368e-13
K51: 1877 | L51: 2.2737368e-13
K52: 1770 | L52: -2.2737368e-13
K53: 1676 | L53: 0
K54: 1632 | L54: 0
K55: 1623 | L55: 0

Sheet занятые
A1: СРЕДНЕГОДОВАЯ ЧИСЛЕННОСТЬ ЗАНЯТЫХ
B2: 2010 | C2: 2015 | D2: 2020 | E2: 2021 | F2: 2022 | G2: 2023
A3: Российская Федерация | B3: 71493.1 | C3: 72424.9 | D3: 69550.3 | E3: 70817.9 | F3: 71216.9 | G3: 72911.8
A4: Центральный | B4: 20 782,3 | C4: 21 178,0 | D4: 20765.6 | E4: 20906.2 | F4: 20 843,9 | G4: 21537.9
A5: федеральный округ
A6: Белгородская область | B6: 749.8 | C6: 754 | D6: 751.9 | E6: 761.5 | F6: 771.2 | G6: 765.3
A7: Брянская область | B7: 580.9 | C7: 547.7 | D7: 498.5 | E7: 511.3 | F7: 506.7 | G7: 504.5
A8: Владимирская область | B8: 670.5 | C8: 664.4 | D8: 618.6 | E8: 616.1 | F8: 647.7 | G8: 639
A9: Воронежская область | B9: 1 158,9 | C9: 1 092,5 | D9: 1088.1 | E9: 1112.9 | F9: 1 135,4 | G9: 1151.6
A10: Ивановская область | B10: 467.8 | C10: 451.5 | D10: 428.6 | E10: 443.5 | F10: 448.5 | G10: 422.2
A11: Калужская область | B11: 516.8 | C11: 508 | D11: 495 | E11: 508.6 | F11: 503.1 | G11: 536.9
A12: Костромская область | B12: 327.5 | C12: 299.4 | D12: 271.9 | E12: 273.7 | F12: 277.9 | G12: 257.3
A13: Курская область | B13: 546.4 | C13: 520.3 | D13: 492.1 | E13: 509.3 | F13: 512.3 | G13: 502.6
A14: Липецкая область | B14: 594.5 | C14: 565.2 | D14: 556 | E14: 559.4 | F14: 549.5 | G14: 565.7
A15: Московская область | B15: 3 341,4 | C15: 3 366,9 | D15: 3422.7 | E15: 3488.4 | F15: 3 452,4 | G15: 3991.8
A16: Орловская область | B16: 342.5 | C16: 335.9 | D16: 293.8 | E16: 299.2 | F16: 297.8 | G16: 301.5
A17: Рязанская область | B17: 529 | C17: 504.8 | D17: 472.7 | E17: 487.2 | F17: 495.3 | G17: 499.7
A18: Смоленская область | B18: 484.6 | C18: 460.8 | D18: 407.2 | E18: 411.6 | F18: 423.4 | G18: 409.6
A19: Тамбовская область | B19: 504 | C19: 499.8 | D19: 449 | E19: 451.8 | F19: 462.3 | G19: 459.9
A20: Тверская область | B20: 676.8 | C20: 630.1 | D20: 576 | E20: 571.3 | F20: 575.2 | G20: 578.2
A21: Тульская область | B21: 770 | C21: 742.6 | D21: 705.1 | E21: 713 | F21: 716 | G21: 736.3
A22: Ярославская область | B22: 649.1 | C22: 635.9 | D22: 597.5 | E22: 611.5 | F22: 603 | G22: 598.7
A23: г. Москва | B23: 7 871,8 | C23: 8 598,0 | D23: 8641 | E23: 8576 | F23: 8 466,1 | G23: 8617.1
A24: Северо-Западный | B24: 7 286,3 | C24: 7 296,8 | D24: 6954.2 | E24: 7047.9 | F24: 7 138,5 | G24: 7221.2
A25: федеральный округ
A26: Республика Карелия | B26: 310.7 | C26: 284 | D26: 260.1 | E26: 264.9 | F26: 264.9 | G26: 235.1
A27: Республика Коми | B27: 472.6 | C27: 437.7 | D27: 383.2 | E27: 377.3 | F27: 368.9 | G27: 335.6
A28: Архангельская область | B28: 575.6 | C28: 558.4 | D28: 497.7 | E28: 509.1 | F28: 510.8 | G28: 460.5
A29: в том числе:
A30: Ненецкий автономный округ | B30: 32.5 | C30: 33.3 | D30: 31.2 | E30: 30 | F30: 31.4 | G30: 30.7
A31: Архангельская область без автономного округа | B31: 543.1 | C31: 525.1 | D31: 466.5 | E31: 479.1 | F31: 479.5 | G31: 429.8
A32: Вологодская область | B32: 608.6 | C32: 554.1 | D32: 517.6 | E32: 515.1 | F32: 517.7 | G32: 503.2
A33: Калининградская область | B33: 484.5 | C33: 478.2 | D33: 472.8 | E33: 489.7 | F33: 506.7 | G33: 519.3
A34: Ленинградская область | B34: 837.2 | C34: 842.1 | D34: 782.6 | E34: 800.7 | F34: 871.1 | G34: 901.5
A35: Мурманская область | B35: 417.9 | C35: 383.2 | D35: 348.3 | E35: 356.5 | F35: 340.9 | G35: 313.2
A36: Новгородская область | B36: 315 | C36: 298.7 | D36: 258.8 | E36: 264.5 | F36: 268.1 | G36: 273.8
A37: Псковская область | B37: 310.5 | C37: 295.6 | D37: 272 | E37: 274.5 | F37: 275.9 | G37: 285.2
A38: г. Санкт-Петербург | B38: 2 953,7 | C38: 3 164,8 | D38: 3161.1 | E38: 3195.6 | F38: 3 213,6 | G38: 3393.9
A39: Южный | B39: 6 478,6 | C39: 7 442,5 | D39: 7328.9 | E39: 7563.7 | F39: 7 695,5 | G39: 8057.6
A40: федеральный округ
...

Sheet Доход
A1: РЕАЛЬНЫЕ ДЕНЕЖНЫЕ ДОХОДЫ НАСЕЛЕНИЯ (в процентах к предыдущему году)
B2: 2010 | C2: 2015 | D2: 2020 | E2: 2021 | F2: 2022 | G2: 2023 | H2: Место, занима-емоев Российской Федерации 2023
A3: Российская Федерация | B3: 18 958 | C3: 30140 | D3: 35934 | E3: 39934 | F3: 47 386 | G3: 53579
A4: Центральный | B4: 24 645 | C4: 38351 | D4: 47318 | E4: 53244 | F4: 62 684 | G4: 71 914 | H4: 1
A5: федеральный округ
A6: Белгородская область | B6: 16 993 | C6: 28006 | D6: 32799 | E6: 35511 | F6: 41855 | G6: 47257 | H6: 25
A7: Брянская область | B7: 13 358 | C7: 23479 | D7: 28720 | E7: 31713 | F7: 37428 | G7: 40927 | H7: 49
A8: Владимирская область | B8: 12 956 | C8: 22593 | D8: 25649 | E8: 28148 | F8: 34667 | G8: 38649 | H8: 62
A9: Воронежская область | B9: 13 883 | C9: 29291 | D9: 31925 | E9: 34982 | F9: 41156 | G9: 45087 | H9: 31
A10: Ивановская область | B10: 11 124 | C10: 22783 | D10: 27558 | E10: 30235 | F10: 36509 | G10: 41108 | H10: 48
A11: Калужская область | B11: 15 477 | C11: 26787 | D11: 30943 | E11: 33174 | F11: 39423 | G11: 44564 | H11: 32
A12: Костромская область | B12: 13 315 | C12: 22550 | D12: 27408 | E12: 30567 | F12: 37285 | G12: 43668 | H12: 35
A13: Курская область | B13: 14 685 | C13: 25383 | D13: 29917 | E13: 32871 | F13: 39401 | G13: 43719 | H13: 34
A14: Липецкая область | B14: 15 936 | C14: 26864 | D14: 31932 | E14: 34509 | F14: 41177 | G14: 45458 | H14: 30
A15: Московская область | B15: 22 641 | C15: 36170 | D15: 43332 | E15: 49213 | F15: 55746 | G15: 64870 | H15: 12
A16: Орловская область | B16: 13 115 | C16: 22152 | D16: 27121 | E16: 30008 | F16: 35923 | G16: 43730 | H16: 33
A17: Рязанская область | B17: 13 886 | C17: 23578 | D17: 27044 | E17: 30142 | F17: 36431 | G17: 39905 | H17: 53
... A23: г. Москва | B23: 44 051 | C23: 60465 | D23: 76320 | E23: 86453 | F23: 102143 | G23: 117103 | H23: 4
A24: Северо-Западный | B24: 19 837 | C24: 31256 | D24: 39502 | E24: 44623 | F24: 52 455 | G24: 58 669 | H24: 2
A25: федеральный округ
A26: Республика Карелия | B26: 16 046 | C26: 27118 | D26: 36504 | E26: 39929 | F26: 46019 | G26: 53068 | H26: 20
A27: Республика Коми | B27: 22 260 | C27: 32331 | D27: 39601 | E27: 42603 | F27: 50840 | G27: 56152 | H27: 14
A28: Архангельская область | B28: 19 609 | C28: 32434 | D28: 39788 | E28: 43381 | F28: 52050 | G28: 58967
A29: в том числе:
A30: Ненецкий автономный округ | B30: 52 270 | C30: 74218 | D30: 89570 | E30: 92620 | F30: 115336 | G30: 128204 | H30: 3
A31: Архангельская область без автономного округа | C31: 30816 | D31: 37728 | E31: 41307 | F31: 49 347 | G31: 55 952 | H31: 15
A32: без автономного округа
A33: Вологодская область | B33: 14 115 | C33: 25002 | D33: 29706 | E33: 31887 | F33: 37178 | G33: 42708 | H33: 41
A34: Калининградская область | B34: 16 040 | C34: 25476 | D34: 29536 | E34: 31934 | F34: 38327 | G34: 43543 | H34: 36
A35: Ленинградская область | B35: 14 798 | C35: 25008 | D35: 31884 | E35: 35199 | F35: 40790 | G35: 45989 | H35: 28
A36: Мурманская область | B36: 24 047 | C36: 38001 | D36: 50139 | E36: 55506 | F36: 65707 | G36: 75786 | H36: 8
A37: Новгородская область | B37: 15 599 | C37: 25712 | D37: 26606 | E37: 29517 | F37: 34201 | G37: 38903 | H37: 61
A38: Псковская область | B38: 12 798 | C38: 21762 | D38: 27069 | E38: 30127 | F38: 35031 | G38: 39898 | H38: 54
A39: г. Санкт-Петербург | B39: 24 824 | C39: 36757 | D39: 47664 | E39: 55679 | F39: 65395 | G39: 72037 | H39: 10
A40: Южный | B40: 15 114 | C40: 25157 | D40: 30413 | E40: 34431 | F40: 40 219 | G40: 45 063 | H40: 5
A41: федеральный округ
A42: Республика Адыгея | B42: 12 279 | C42: 22417 | D42: 28716 | E42: 32882 | F42: 36627 | G42: 42684 | H42: 43
A43: Республика Калмыкия | B43: 7 774 | C43: 15325 | D43: 19892 | E43: 21415 | F43: 23771 | G43: 28635 | H43: 83
A44: Республика Крым | C44: 15641 | D44: 22698 | E44: 25937 | F44: 29817 | G44: 32875 | H44: 79
A45: Краснодарский край | B45: 16 892 | C45: 30970 | D45: 36547 | E45: 42228 | F45: 48684 | G45: 54627 | H45: 16
...

Sheet Темп роста
B1: Численность | C1: Реальные | D1: Реальные | E1: Реальная | F1: Валовой | G1: Инвестиции | H1: Промышленное производство2) | I1: Продукция | J1: в том числе | L1: Ввод | M1: Оборот | N1: Производи- | O1: Сальдиро-ванный финансовый
B2: населения | C2: денежные | D2: потреби- | E2: начисленная | F2: региональ- | G2: в основной | I2: сельского | L2: в действие | M2: розничной | N2: тельность труда | O2: результат
B3: на 1 января | C3: доходы | D3: тельские | E3: заработная плата работ- | F3: ный продукт | G3: капитал | I3: хозяйства – | L3: жилых | M3: торговли | N3: в 2022 г.3) | O3: (прибыль минус убы-ток) дея-тельности
B4: 2024 г. | C4: населения | D4: расходы | E4: ников орга- | F4: в 2022 г.1) | I4: всего | L4: домов | O4: организаций
D5: населения | E5: низаций | O5: (в фактичес-ки действо-вавших
J6: растение- | K6: животно- | O6: ценах)4)
J7: водства | K7: водства
A8: Российская Федерация | B8: 99.8 | C8: 106.5 | D8: 108.6 | E8: 108.2 | F8: 100.3 | G8: 109.8 | H8: 104.1 | I8: 100.2 | J8: 99.7 | K8: 100.9 | L8: 107.5 | M8: 108 | N8: 97.2 | O8: 156 | P8: Российская Федерация
A9: Центральный | B9: 99.9 | C9: 107.9 | D9: 107.8 | E9: 106.8 | F9: 98.8 | G9: 103.6 | H9: 116 | I9: 106.6 | J9: 109.2 | K9: 103.2 | L9: 100.3 | M9: 106.7 | O9: 173.6 | P9: Центральный
A10: федеральный округ | P10: федеральный округ
A11: Белгородская область | B11: 99.1 | C11: 105.2 | D11: 101.5 | E11: 107.8 | F11: 99.2 | G11: 99 | H11: 104.7 | I11: 105 | J11: 108.7 | K11: 102.6 | L11: 114.1 | M11: 99.2 | N11: 96.7 | O11: 126.1 | P11: Белгородская область
A12: Брянская область | B12: 99.1 | C12: 101.2 | D12: 98.2 | E12: 110.1 | F12: 99.9 | G12: 93.4 | H12: 115.8 | I12: 115.9 | J12: 118.9 | K12: 112.8 | L12: 117 | M12: 97.6 | N12: 101.9 | O12: 134.3 | P12: Брянская область
A13: Владимирская область | B13: 98.8 | C13: 103.7 | D13: 104 | E13: 109.9 | F13: 93.4 | G13: 91.2 | H13: 109.3 | I13: 105.7 | J13: 109.6 | K13: 103.5 | L13: 96.8 | M13: 103.4 | N13: 90 | O13: 102 | P13: Владимирская область
A14: Воронежская область | B14: 99.5 | C14: 103.3 | D14: 104.4 | E14: 109.3 | F14: 97.6 | G14: 100.5 | H14: 109.9 | I14: 103.3 | J14: 105.3 | K14: 100 | L14: 104.8 | M14: 104.6 | N14: 94.6 | O14: 109.9 | P14: Воронежская область
A15: Ивановская область | B15: 99 | C15: 105.9 | D15: 102.4 | E15: 109.5 | F15: 100 | G15: 97.8 | H15: 110 | I15: 108.5 | J15: 114.9 | K15: 104.1 | L15: 130.5 | M15: 102 | N15: 99.5 | O15: 142.2 | P15: Ивановская область
A16: Калужская область | B16: 99.8 | C16: 105.6 | D16: 104.5 | E16: 106.9 | F16: 88.5 | G16: 79.6 | H16: 111 | I16: 106.3 | J16: 106 | K16: 106.6 | L16: 122.1 | M16: 103.6 | N16: 89.4 | O16: 14.6 | P16: Калужская область
A17: Костромская область | B17: 99 | C17: 107.8 | D17: 102.9 | E17: 108 | F17: 98.3 | G17: 114.4 | H17: 108.7 | I17: 105.6 | J17: 111.1 | K17: 102.9 | L17: 106.8 | M17: 100.6 | N17: 97.1 | O17: – | P17: Костромская область
A18: Курская область | B18: 99.4 | C18: 103.5 | D18: 102 | E18: 109.4 | F18: 94.6 | G18: 102.9 | H18: 111.3 | I18: 105 | J18: 105.2 | K18: 104.5 | L18: 111.9 | M18: 101.4 | N18: 92.8 | O18: 89.9 | P18: Курская область
A19: Липецкая область | B19: 99.1 | C19: 103.3 | D19: 101.1 | E19: 109.4 | F19: 92 | G19: 104.1 | H19: 108.9 | I19: 103.5 | J19: 105.6 | K19: 98.6 | L19: 102.1 | M19: 100.4 | N19: 93.3 | O19: 129.8 | P19: Липецкая область
A20: Московская область | B20: 100.7 | C20: 108.8 | D20: 107.5 | E20: 109.3 | F20: 95 | G20: 106.2 | H20: 116.2 | I20: 103.1 | J20: 107.3 | K20: 96.9 | L20: 88.6 | M20: 109.6 | N20: 96.5 | O20: 158.5 | P20: Московская область
A21: Орловская область | B21: 98.9 | C21: 113.8 | D21: 103.3 | E21: 109.9 | F21: 97.1 | G21: 88.3 | H21: 103.6 | I21: 114.3 | J21: 117.1 | K21: 107.3 | L21: 100.1 | M21: 102.6 | N21: 96.2 | O21: 138.8 | P21: Орловская область
A22: Рязанская область | B22: 99.4 | C22: 102.8 | D22: 105.4 | E22: 110.1 | F22: 101.7 | G22: 102.1 | H22: 108.6 | I22: 105.5 | J22: 104.1 | K22: 107.6 | L22: 97.8 | M22: 105.6 | N22: 101.1 | O22: 118.5 | P22: Рязанская область
A23: Смоленская область | B23: 99 | C23: 113.6 | D23: 106.1 | E23: 113.2 | F23: 100.1 | G23: 128.9 | H23: 111.1 | I23: 100.7 | J23: 100.3 | K23: 101 | L23: 100.4 | M23: 107.3 | N23: 96.8 | O23: 131.5 | P23: Смоленская область
A24: Тамбовская область | B24: 99 | C24: 105 | D24: 100.9 | E24: 109.5 | F24: 98.1 | G24: 104.6 | H24: 112.3 | I24: 111.1 | J24: 120.5 | K24: 95.2 | L24: 119.3 | M24: 100.8 | N24: 96.3 | O24: 117.4 | P24: Тамбовская область
A25: Тверская область | B25: 99.1 | C25: 107.3 | D25: 106.7 | E25: 112 | F25: 96.9 | G25: 145.4 | H25: 115.4 | I25: 116.5 | J25: 118 | K25: 115.9 | L25: 107.5 | M25: 107.6 | N25: 97 | O25: 133.3 | P25: Тверская область
A26: Тульская область | B26: 99.3 | C26: 107 | D26: 111.5 | E26: 111.7 | F26: 104.1 | G26: 101.6 | H26: 117.1 | I26: 107.1 | J26: 107.9 | K26: 105.6 | L26: 120.9 | M26: 111 | N26: 104.2 | O26: 113 | P26: Тульская область
A27: Ярославская область | B27: 99.4 | C27: 108.4 | D27: 103.8 | E27: 111.5 | F27: 97 | G27: 106.1 | H27: 106.9 | I27: 105.1 | J27: 105.6 | K27: 104.9 | L27: 119.8 | M27: 105.2 | N27: 98.5 | O27: 120.9 | P27: Ярославская область
A28: г. Москва | B28: 100.3 | C28: 109 | D28: 110.4 | E28: 104.4 | F28: 100.6 | G28: 103.8 | H28: 118.7 | I28: 70.8 | J28: 70.2 | K28: 81.2 | L28: 108 | M28: 107.5 | N28: 101.3 | O28: 190.4 | P28: г. Москва
A29: Северо-Западный | B29: 99.8 | C29: 105.4 | D29: 111.7 | E29: 106.1 | F29: 97.5 | G29: 104.3 | H29: 104.9 | I29: 100.8 | J29: 99.4 | K29: 101.4 | L29: 101.7 | M29: 113.1 | O29: 120.7 | P29: Северо-Западный
A30: федеральный округ | P30: федеральный округ
A31: Республика Карелия | B31: 99.2 | C31: 107.9 | D31: 110 | E31: 108.2 | F31: 91 | G31: 95.7 | H31: 100.2 | I31: 99.9 | J31: 99.4 | K31: 100.3 | L31: 100.8 | M31: 112.2 | N31: 90.6 | O31: 60.8 | P31: Республика Карелия
A32: Республика Коми | B32: 99.2 | C32: 103.4 | D32: 102.6 | E32: 106.6 | F32: 99.9 | G32: 98.5 | H32: 100.5 | I32: 94.6 | J32: 101.4 | K32: 91.6 | L32: 107.1 | M32: 105.8 | N32: 102.1 | O32: 63.8 | P32: Республика Коми
A33: Архангельская область | B33: 99.2 | C33: 105.9 | D33: 103.9 | E33: 106.2 | F33: 102.5 | G33: 98.7 | H33: 95.9 | I33: 101.6 | J33: 99 | K33: 103.9 | L33: 100 | M33: 102.9 | N33: 102.1 | O33: 69.9 | P33: Архангельская область
A34: в том числе: | P34: в том числе:
A35: Ненецкий автономный округ | B35: 102 | C35: 105 | D35: 102.5 | E35: 104.4 | F35: 112.3 | G35: 94.4 | H35: 93.7 | I35: 102.8 | J35: 100.1 | K35: 103.2 | L35: 60.8 | M35: 103.7 | N35: 107.9 | O35: 34 | P35: Ненецкий автономный округ
A36: Архангельская область | B36: 99.1 | C36: 105.9 | D36: 104 | E36: 106.2 | F36: 96.5 | G36: 100.8 | H36: 99.2 | I36: 101.5 | J36: 99 | K36: 104 | L36: 103.3 | M36: 102.8 | N36: 96 | O36: 87.1 | P36: Архангельская область
A37: без автономного округа | P37: без автономного округа
A38: Вологодская область | B38: 99.3 | C38: 107.4 | D38: 103.9 | E38: 103.7 | F38: 95.2 | G38: 86.7 | H38: 106.2 | I38: 101.7 | J38: 102.8 | K38: 101.2 | L38: 115.1 | M38: 102.6 | N38: 95.1 | O38: 62.8 | P38: Вологодская область
